{
 "cells": [
  {
   "cell_type": "code",
   "execution_count": 8,
   "metadata": {},
   "outputs": [],
   "source": [
    "from google.oauth2 import id_token\n",
    "from google.auth.transport import requests\n",
    "import sqlalchemy as db\n",
    "\n"
   ]
  },
  {
   "cell_type": "code",
   "execution_count": 5,
   "metadata": {},
   "outputs": [],
   "source": [
    "\n",
    "token = \"eyJhbGciOiJSUzI1NiIsImtpZCI6IjIwOWMwNTdkM2JkZDhjMDhmMmQ1NzM5Nzg4NjMyNjczZjdjNjI0MGYiLCJ0eXAiOiJKV1QifQ.eyJpc3MiOiJodHRwczovL2FjY291bnRzLmdvb2dsZS5jb20iLCJuYmYiOjE2NjM3MTEwOTksImF1ZCI6IjczMjI2NDA1MTQzNi0wamdqZXIyMW50bm9pNW92aWxtZ3RxcGdoYWoyODZzdi5hcHBzLmdvb2dsZXVzZXJjb250ZW50LmNvbSIsInN1YiI6IjEwMTQ1MzQ2NjE3NTM4OTYxMzEwNiIsImVtYWlsIjoicGhpbGlwcGUuaGVucmkuc2FhZGVAZ21haWwuY29tIiwiZW1haWxfdmVyaWZpZWQiOnRydWUsImF6cCI6IjczMjI2NDA1MTQzNi0wamdqZXIyMW50bm9pNW92aWxtZ3RxcGdoYWoyODZzdi5hcHBzLmdvb2dsZXVzZXJjb250ZW50LmNvbSIsIm5hbWUiOiJQaGlsaXBwZSBTYWFkZSIsInBpY3R1cmUiOiJodHRwczovL2xoMy5nb29nbGV1c2VyY29udGVudC5jb20vYS9BTG01d3UyWDA5a1QxSThfd3k5YnVjc0N5WHdxUGM2OVJWLTlMU2RZbW5HUT1zOTYtYyIsImdpdmVuX25hbWUiOiJQaGlsaXBwZSIsImZhbWlseV9uYW1lIjoiU2FhZGUiLCJpYXQiOjE2NjM3MTEzOTksImV4cCI6MTY2MzcxNDk5OSwianRpIjoiYTczMjA3MTVhNTQyNjJmNTY0YmU3OTVhNjVlNTM3Mjc2NzNkOWE4MiJ9.opekYQppXFiRVnmAw8UUzdsP1xU0LJKrIfeTII3j0j9GNM2LaiBNELxydiVpQPoXYMoPSkA6KC8IVjAmL-a5o6RsKh5MFDrIEomWDXkza2sEsqEaLiAofOmpgVz8iMp3IiKhscrhuuY912ORYfv8AyK2Up4Z2Q25UkPCnI0Ksn6QP5dRiUGbo1Bno_oQSuDOVYzYwvQD6DakkfLqPbnEog3kWHb16mePriKXScRwkCnXPZ_CYDPvv9P-itY63kvp9VXcN-qurmMFf0KpYdpVozLL41MNen4LjNKqbZKpfIUu0KbgEGjB4IRMcdtRGSO8p66EgDqkO_ge6TfJNyiQiA\"\n",
    "client_id = \"732264051436-0jgjer21ntnoi5ovilmgtqpghaj286sv.apps.googleusercontent.com\"\n"
   ]
  },
  {
   "cell_type": "code",
   "execution_count": 6,
   "metadata": {},
   "outputs": [],
   "source": [
    "idinfo = id_token.verify_oauth2_token(token, requests.Request(), client_id)\n"
   ]
  },
  {
   "cell_type": "code",
   "execution_count": 14,
   "metadata": {},
   "outputs": [],
   "source": [
    "\n",
    "def connect_unix_socket() -> db.engine.base.Engine:\n",
    "    db_user = \"root\" # e.g. 'my-database-user'\n",
    "    db_pass = \"sql&kollaidu31\"  # e.g. 'my-database-password'\n",
    "    db_name = \"kollai_data\"  # e.g. 'my-database'\n",
    "    unix_socket_path = \"/cloudsql/ai-canvas:europe-west1:sql-server\" # e.g. '/cloudsql/project:region:instance'\n",
    "\n",
    "    pool = db.create_engine(\n",
    "        db.engine.url.URL.create(\n",
    "            drivername=\"mysql+pymysql\",\n",
    "            username=db_user,\n",
    "            password=db_pass,\n",
    "            database=db_name,\n",
    "            query={\"unix_socket\": unix_socket_path},),)\n",
    "            \n",
    "    return pool"
   ]
  },
  {
   "cell_type": "code",
   "execution_count": 11,
   "metadata": {},
   "outputs": [],
   "source": [
    "def get_or_create(session, model, **kwargs):\n",
    "    instance = session.query(model).filter_by(**kwargs).first()\n",
    "    if instance:\n",
    "        return instance\n",
    "    else:\n",
    "        instance = model(**kwargs)\n",
    "        session.add(instance)\n",
    "        return instance\n",
    "        "
   ]
  },
  {
   "cell_type": "code",
   "execution_count": 16,
   "metadata": {},
   "outputs": [],
   "source": [
    "engine = connect_unix_socket()\n",
    "\n"
   ]
  },
  {
   "cell_type": "code",
   "execution_count": 17,
   "metadata": {},
   "outputs": [
    {
     "ename": "OperationalError",
     "evalue": "(pymysql.err.OperationalError) (2003, \"Can't connect to MySQL server on 'localhost' ([WinError 10061] Aucune connexion n’a pu être établie car l’ordinateur cible l’a expressément refusée)\")\n(Background on this error at: https://sqlalche.me/e/14/e3q8)",
     "output_type": "error",
     "traceback": [
      "\u001b[1;31m---------------------------------------------------------------------------\u001b[0m",
      "\u001b[1;31mConnectionRefusedError\u001b[0m                    Traceback (most recent call last)",
      "File \u001b[1;32mc:\\Users\\filou\\anaconda3\\envs\\dashcanvas\\lib\\site-packages\\pymysql\\connections.py:613\u001b[0m, in \u001b[0;36mConnection.connect\u001b[1;34m(self, sock)\u001b[0m\n\u001b[0;32m    612\u001b[0m \u001b[39mtry\u001b[39;00m:\n\u001b[1;32m--> 613\u001b[0m     sock \u001b[39m=\u001b[39m socket\u001b[39m.\u001b[39mcreate_connection(\n\u001b[0;32m    614\u001b[0m         (\u001b[39mself\u001b[39m\u001b[39m.\u001b[39mhost, \u001b[39mself\u001b[39m\u001b[39m.\u001b[39mport), \u001b[39mself\u001b[39m\u001b[39m.\u001b[39mconnect_timeout, \u001b[39m*\u001b[39m\u001b[39m*\u001b[39mkwargs\n\u001b[0;32m    615\u001b[0m     )\n\u001b[0;32m    616\u001b[0m     \u001b[39mbreak\u001b[39;00m\n",
      "File \u001b[1;32mc:\\Users\\filou\\anaconda3\\envs\\dashcanvas\\lib\\socket.py:845\u001b[0m, in \u001b[0;36mcreate_connection\u001b[1;34m(address, timeout, source_address)\u001b[0m\n\u001b[0;32m    844\u001b[0m \u001b[39mtry\u001b[39;00m:\n\u001b[1;32m--> 845\u001b[0m     \u001b[39mraise\u001b[39;00m err\n\u001b[0;32m    846\u001b[0m \u001b[39mfinally\u001b[39;00m:\n\u001b[0;32m    847\u001b[0m     \u001b[39m# Break explicitly a reference cycle\u001b[39;00m\n",
      "File \u001b[1;32mc:\\Users\\filou\\anaconda3\\envs\\dashcanvas\\lib\\socket.py:833\u001b[0m, in \u001b[0;36mcreate_connection\u001b[1;34m(address, timeout, source_address)\u001b[0m\n\u001b[0;32m    832\u001b[0m     sock\u001b[39m.\u001b[39mbind(source_address)\n\u001b[1;32m--> 833\u001b[0m sock\u001b[39m.\u001b[39;49mconnect(sa)\n\u001b[0;32m    834\u001b[0m \u001b[39m# Break explicitly a reference cycle\u001b[39;00m\n",
      "\u001b[1;31mConnectionRefusedError\u001b[0m: [WinError 10061] Aucune connexion n’a pu être établie car l’ordinateur cible l’a expressément refusée",
      "\nDuring handling of the above exception, another exception occurred:\n",
      "\u001b[1;31mOperationalError\u001b[0m                          Traceback (most recent call last)",
      "File \u001b[1;32mc:\\Users\\filou\\anaconda3\\envs\\dashcanvas\\lib\\site-packages\\sqlalchemy\\engine\\base.py:3361\u001b[0m, in \u001b[0;36mEngine._wrap_pool_connect\u001b[1;34m(self, fn, connection)\u001b[0m\n\u001b[0;32m   3360\u001b[0m \u001b[39mtry\u001b[39;00m:\n\u001b[1;32m-> 3361\u001b[0m     \u001b[39mreturn\u001b[39;00m fn()\n\u001b[0;32m   3362\u001b[0m \u001b[39mexcept\u001b[39;00m dialect\u001b[39m.\u001b[39mdbapi\u001b[39m.\u001b[39mError \u001b[39mas\u001b[39;00m e:\n",
      "File \u001b[1;32mc:\\Users\\filou\\anaconda3\\envs\\dashcanvas\\lib\\site-packages\\sqlalchemy\\pool\\base.py:320\u001b[0m, in \u001b[0;36mPool.connect\u001b[1;34m(self)\u001b[0m\n\u001b[0;32m    313\u001b[0m \u001b[39m\"\"\"Return a DBAPI connection from the pool.\u001b[39;00m\n\u001b[0;32m    314\u001b[0m \n\u001b[0;32m    315\u001b[0m \u001b[39mThe connection is instrumented such that when its\u001b[39;00m\n\u001b[1;32m   (...)\u001b[0m\n\u001b[0;32m    318\u001b[0m \n\u001b[0;32m    319\u001b[0m \u001b[39m\"\"\"\u001b[39;00m\n\u001b[1;32m--> 320\u001b[0m \u001b[39mreturn\u001b[39;00m _ConnectionFairy\u001b[39m.\u001b[39;49m_checkout(\u001b[39mself\u001b[39;49m)\n",
      "File \u001b[1;32mc:\\Users\\filou\\anaconda3\\envs\\dashcanvas\\lib\\site-packages\\sqlalchemy\\pool\\base.py:884\u001b[0m, in \u001b[0;36m_ConnectionFairy._checkout\u001b[1;34m(cls, pool, threadconns, fairy)\u001b[0m\n\u001b[0;32m    883\u001b[0m \u001b[39mif\u001b[39;00m \u001b[39mnot\u001b[39;00m fairy:\n\u001b[1;32m--> 884\u001b[0m     fairy \u001b[39m=\u001b[39m _ConnectionRecord\u001b[39m.\u001b[39;49mcheckout(pool)\n\u001b[0;32m    886\u001b[0m     fairy\u001b[39m.\u001b[39m_pool \u001b[39m=\u001b[39m pool\n",
      "File \u001b[1;32mc:\\Users\\filou\\anaconda3\\envs\\dashcanvas\\lib\\site-packages\\sqlalchemy\\pool\\base.py:486\u001b[0m, in \u001b[0;36m_ConnectionRecord.checkout\u001b[1;34m(cls, pool)\u001b[0m\n\u001b[0;32m    484\u001b[0m \u001b[39m@classmethod\u001b[39m\n\u001b[0;32m    485\u001b[0m \u001b[39mdef\u001b[39;00m \u001b[39mcheckout\u001b[39m(\u001b[39mcls\u001b[39m, pool):\n\u001b[1;32m--> 486\u001b[0m     rec \u001b[39m=\u001b[39m pool\u001b[39m.\u001b[39;49m_do_get()\n\u001b[0;32m    487\u001b[0m     \u001b[39mtry\u001b[39;00m:\n",
      "File \u001b[1;32mc:\\Users\\filou\\anaconda3\\envs\\dashcanvas\\lib\\site-packages\\sqlalchemy\\pool\\impl.py:145\u001b[0m, in \u001b[0;36mQueuePool._do_get\u001b[1;34m(self)\u001b[0m\n\u001b[0;32m    144\u001b[0m \u001b[39mexcept\u001b[39;00m:\n\u001b[1;32m--> 145\u001b[0m     \u001b[39mwith\u001b[39;00m util\u001b[39m.\u001b[39msafe_reraise():\n\u001b[0;32m    146\u001b[0m         \u001b[39mself\u001b[39m\u001b[39m.\u001b[39m_dec_overflow()\n",
      "File \u001b[1;32mc:\\Users\\filou\\anaconda3\\envs\\dashcanvas\\lib\\site-packages\\sqlalchemy\\util\\langhelpers.py:70\u001b[0m, in \u001b[0;36msafe_reraise.__exit__\u001b[1;34m(self, type_, value, traceback)\u001b[0m\n\u001b[0;32m     69\u001b[0m     \u001b[39mif\u001b[39;00m \u001b[39mnot\u001b[39;00m \u001b[39mself\u001b[39m\u001b[39m.\u001b[39mwarn_only:\n\u001b[1;32m---> 70\u001b[0m         compat\u001b[39m.\u001b[39;49mraise_(\n\u001b[0;32m     71\u001b[0m             exc_value,\n\u001b[0;32m     72\u001b[0m             with_traceback\u001b[39m=\u001b[39;49mexc_tb,\n\u001b[0;32m     73\u001b[0m         )\n\u001b[0;32m     74\u001b[0m \u001b[39melse\u001b[39;00m:\n",
      "File \u001b[1;32mc:\\Users\\filou\\anaconda3\\envs\\dashcanvas\\lib\\site-packages\\sqlalchemy\\util\\compat.py:208\u001b[0m, in \u001b[0;36mraise_\u001b[1;34m(***failed resolving arguments***)\u001b[0m\n\u001b[0;32m    207\u001b[0m \u001b[39mtry\u001b[39;00m:\n\u001b[1;32m--> 208\u001b[0m     \u001b[39mraise\u001b[39;00m exception\n\u001b[0;32m    209\u001b[0m \u001b[39mfinally\u001b[39;00m:\n\u001b[0;32m    210\u001b[0m     \u001b[39m# credit to\u001b[39;00m\n\u001b[0;32m    211\u001b[0m     \u001b[39m# https://cosmicpercolator.com/2016/01/13/exception-leaks-in-python-2-and-3/\u001b[39;00m\n\u001b[0;32m    212\u001b[0m     \u001b[39m# as the __traceback__ object creates a cycle\u001b[39;00m\n",
      "File \u001b[1;32mc:\\Users\\filou\\anaconda3\\envs\\dashcanvas\\lib\\site-packages\\sqlalchemy\\pool\\impl.py:143\u001b[0m, in \u001b[0;36mQueuePool._do_get\u001b[1;34m(self)\u001b[0m\n\u001b[0;32m    142\u001b[0m \u001b[39mtry\u001b[39;00m:\n\u001b[1;32m--> 143\u001b[0m     \u001b[39mreturn\u001b[39;00m \u001b[39mself\u001b[39;49m\u001b[39m.\u001b[39;49m_create_connection()\n\u001b[0;32m    144\u001b[0m \u001b[39mexcept\u001b[39;00m:\n",
      "File \u001b[1;32mc:\\Users\\filou\\anaconda3\\envs\\dashcanvas\\lib\\site-packages\\sqlalchemy\\pool\\base.py:266\u001b[0m, in \u001b[0;36mPool._create_connection\u001b[1;34m(self)\u001b[0m\n\u001b[0;32m    264\u001b[0m \u001b[39m\"\"\"Called by subclasses to create a new ConnectionRecord.\"\"\"\u001b[39;00m\n\u001b[1;32m--> 266\u001b[0m \u001b[39mreturn\u001b[39;00m _ConnectionRecord(\u001b[39mself\u001b[39;49m)\n",
      "File \u001b[1;32mc:\\Users\\filou\\anaconda3\\envs\\dashcanvas\\lib\\site-packages\\sqlalchemy\\pool\\base.py:381\u001b[0m, in \u001b[0;36m_ConnectionRecord.__init__\u001b[1;34m(self, pool, connect)\u001b[0m\n\u001b[0;32m    380\u001b[0m \u001b[39mif\u001b[39;00m connect:\n\u001b[1;32m--> 381\u001b[0m     \u001b[39mself\u001b[39;49m\u001b[39m.\u001b[39;49m__connect()\n\u001b[0;32m    382\u001b[0m \u001b[39mself\u001b[39m\u001b[39m.\u001b[39mfinalize_callback \u001b[39m=\u001b[39m deque()\n",
      "File \u001b[1;32mc:\\Users\\filou\\anaconda3\\envs\\dashcanvas\\lib\\site-packages\\sqlalchemy\\pool\\base.py:677\u001b[0m, in \u001b[0;36m_ConnectionRecord.__connect\u001b[1;34m(self)\u001b[0m\n\u001b[0;32m    676\u001b[0m \u001b[39mexcept\u001b[39;00m \u001b[39mException\u001b[39;00m \u001b[39mas\u001b[39;00m e:\n\u001b[1;32m--> 677\u001b[0m     \u001b[39mwith\u001b[39;00m util\u001b[39m.\u001b[39msafe_reraise():\n\u001b[0;32m    678\u001b[0m         pool\u001b[39m.\u001b[39mlogger\u001b[39m.\u001b[39mdebug(\u001b[39m\"\u001b[39m\u001b[39mError on connect(): \u001b[39m\u001b[39m%s\u001b[39;00m\u001b[39m\"\u001b[39m, e)\n",
      "File \u001b[1;32mc:\\Users\\filou\\anaconda3\\envs\\dashcanvas\\lib\\site-packages\\sqlalchemy\\util\\langhelpers.py:70\u001b[0m, in \u001b[0;36msafe_reraise.__exit__\u001b[1;34m(self, type_, value, traceback)\u001b[0m\n\u001b[0;32m     69\u001b[0m     \u001b[39mif\u001b[39;00m \u001b[39mnot\u001b[39;00m \u001b[39mself\u001b[39m\u001b[39m.\u001b[39mwarn_only:\n\u001b[1;32m---> 70\u001b[0m         compat\u001b[39m.\u001b[39;49mraise_(\n\u001b[0;32m     71\u001b[0m             exc_value,\n\u001b[0;32m     72\u001b[0m             with_traceback\u001b[39m=\u001b[39;49mexc_tb,\n\u001b[0;32m     73\u001b[0m         )\n\u001b[0;32m     74\u001b[0m \u001b[39melse\u001b[39;00m:\n",
      "File \u001b[1;32mc:\\Users\\filou\\anaconda3\\envs\\dashcanvas\\lib\\site-packages\\sqlalchemy\\util\\compat.py:208\u001b[0m, in \u001b[0;36mraise_\u001b[1;34m(***failed resolving arguments***)\u001b[0m\n\u001b[0;32m    207\u001b[0m \u001b[39mtry\u001b[39;00m:\n\u001b[1;32m--> 208\u001b[0m     \u001b[39mraise\u001b[39;00m exception\n\u001b[0;32m    209\u001b[0m \u001b[39mfinally\u001b[39;00m:\n\u001b[0;32m    210\u001b[0m     \u001b[39m# credit to\u001b[39;00m\n\u001b[0;32m    211\u001b[0m     \u001b[39m# https://cosmicpercolator.com/2016/01/13/exception-leaks-in-python-2-and-3/\u001b[39;00m\n\u001b[0;32m    212\u001b[0m     \u001b[39m# as the __traceback__ object creates a cycle\u001b[39;00m\n",
      "File \u001b[1;32mc:\\Users\\filou\\anaconda3\\envs\\dashcanvas\\lib\\site-packages\\sqlalchemy\\pool\\base.py:673\u001b[0m, in \u001b[0;36m_ConnectionRecord.__connect\u001b[1;34m(self)\u001b[0m\n\u001b[0;32m    672\u001b[0m \u001b[39mself\u001b[39m\u001b[39m.\u001b[39mstarttime \u001b[39m=\u001b[39m time\u001b[39m.\u001b[39mtime()\n\u001b[1;32m--> 673\u001b[0m \u001b[39mself\u001b[39m\u001b[39m.\u001b[39mdbapi_connection \u001b[39m=\u001b[39m connection \u001b[39m=\u001b[39m pool\u001b[39m.\u001b[39;49m_invoke_creator(\u001b[39mself\u001b[39;49m)\n\u001b[0;32m    674\u001b[0m pool\u001b[39m.\u001b[39mlogger\u001b[39m.\u001b[39mdebug(\u001b[39m\"\u001b[39m\u001b[39mCreated new connection \u001b[39m\u001b[39m%r\u001b[39;00m\u001b[39m\"\u001b[39m, connection)\n",
      "File \u001b[1;32mc:\\Users\\filou\\anaconda3\\envs\\dashcanvas\\lib\\site-packages\\sqlalchemy\\engine\\create.py:578\u001b[0m, in \u001b[0;36mcreate_engine.<locals>.connect\u001b[1;34m(connection_record)\u001b[0m\n\u001b[0;32m    577\u001b[0m             \u001b[39mreturn\u001b[39;00m connection\n\u001b[1;32m--> 578\u001b[0m \u001b[39mreturn\u001b[39;00m dialect\u001b[39m.\u001b[39mconnect(\u001b[39m*\u001b[39mcargs, \u001b[39m*\u001b[39m\u001b[39m*\u001b[39mcparams)\n",
      "File \u001b[1;32mc:\\Users\\filou\\anaconda3\\envs\\dashcanvas\\lib\\site-packages\\sqlalchemy\\engine\\default.py:598\u001b[0m, in \u001b[0;36mDefaultDialect.connect\u001b[1;34m(self, *cargs, **cparams)\u001b[0m\n\u001b[0;32m    596\u001b[0m \u001b[39mdef\u001b[39;00m \u001b[39mconnect\u001b[39m(\u001b[39mself\u001b[39m, \u001b[39m*\u001b[39mcargs, \u001b[39m*\u001b[39m\u001b[39m*\u001b[39mcparams):\n\u001b[0;32m    597\u001b[0m     \u001b[39m# inherits the docstring from interfaces.Dialect.connect\u001b[39;00m\n\u001b[1;32m--> 598\u001b[0m     \u001b[39mreturn\u001b[39;00m \u001b[39mself\u001b[39m\u001b[39m.\u001b[39mdbapi\u001b[39m.\u001b[39mconnect(\u001b[39m*\u001b[39mcargs, \u001b[39m*\u001b[39m\u001b[39m*\u001b[39mcparams)\n",
      "File \u001b[1;32mc:\\Users\\filou\\anaconda3\\envs\\dashcanvas\\lib\\site-packages\\pymysql\\connections.py:353\u001b[0m, in \u001b[0;36mConnection.__init__\u001b[1;34m(self, user, password, host, database, unix_socket, port, charset, sql_mode, read_default_file, conv, use_unicode, client_flag, cursorclass, init_command, connect_timeout, read_default_group, autocommit, local_infile, max_allowed_packet, defer_connect, auth_plugin_map, read_timeout, write_timeout, bind_address, binary_prefix, program_name, server_public_key, ssl, ssl_ca, ssl_cert, ssl_disabled, ssl_key, ssl_verify_cert, ssl_verify_identity, compress, named_pipe, passwd, db)\u001b[0m\n\u001b[0;32m    352\u001b[0m \u001b[39melse\u001b[39;00m:\n\u001b[1;32m--> 353\u001b[0m     \u001b[39mself\u001b[39;49m\u001b[39m.\u001b[39;49mconnect()\n",
      "File \u001b[1;32mc:\\Users\\filou\\anaconda3\\envs\\dashcanvas\\lib\\site-packages\\pymysql\\connections.py:664\u001b[0m, in \u001b[0;36mConnection.connect\u001b[1;34m(self, sock)\u001b[0m\n\u001b[0;32m    663\u001b[0m         \u001b[39mprint\u001b[39m(exc\u001b[39m.\u001b[39mtraceback)\n\u001b[1;32m--> 664\u001b[0m     \u001b[39mraise\u001b[39;00m exc\n\u001b[0;32m    666\u001b[0m \u001b[39m# If e is neither DatabaseError or IOError, It's a bug.\u001b[39;00m\n\u001b[0;32m    667\u001b[0m \u001b[39m# But raising AssertionError hides original error.\u001b[39;00m\n\u001b[0;32m    668\u001b[0m \u001b[39m# So just reraise it.\u001b[39;00m\n",
      "\u001b[1;31mOperationalError\u001b[0m: (2003, \"Can't connect to MySQL server on 'localhost' ([WinError 10061] Aucune connexion n’a pu être établie car l’ordinateur cible l’a expressément refusée)\")",
      "\nThe above exception was the direct cause of the following exception:\n",
      "\u001b[1;31mOperationalError\u001b[0m                          Traceback (most recent call last)",
      "Cell \u001b[1;32mIn [17], line 1\u001b[0m\n\u001b[1;32m----> 1\u001b[0m con \u001b[38;5;241m=\u001b[39m \u001b[43mengine\u001b[49m\u001b[38;5;241;43m.\u001b[39;49m\u001b[43mconnect\u001b[49m\u001b[43m(\u001b[49m\u001b[43m)\u001b[49m\n",
      "File \u001b[1;32mc:\\Users\\filou\\anaconda3\\envs\\dashcanvas\\lib\\site-packages\\sqlalchemy\\engine\\base.py:3315\u001b[0m, in \u001b[0;36mEngine.connect\u001b[1;34m(self, close_with_result)\u001b[0m\n\u001b[0;32m   3300\u001b[0m \u001b[39mdef\u001b[39;00m \u001b[39mconnect\u001b[39m(\u001b[39mself\u001b[39m, close_with_result\u001b[39m=\u001b[39m\u001b[39mFalse\u001b[39;00m):\n\u001b[0;32m   3301\u001b[0m     \u001b[39m\"\"\"Return a new :class:`_engine.Connection` object.\u001b[39;00m\n\u001b[0;32m   3302\u001b[0m \n\u001b[0;32m   3303\u001b[0m \u001b[39m    The :class:`_engine.Connection` object is a facade that uses a DBAPI\u001b[39;00m\n\u001b[1;32m   (...)\u001b[0m\n\u001b[0;32m   3312\u001b[0m \n\u001b[0;32m   3313\u001b[0m \u001b[39m    \"\"\"\u001b[39;00m\n\u001b[1;32m-> 3315\u001b[0m     \u001b[39mreturn\u001b[39;00m \u001b[39mself\u001b[39;49m\u001b[39m.\u001b[39;49m_connection_cls(\u001b[39mself\u001b[39;49m, close_with_result\u001b[39m=\u001b[39;49mclose_with_result)\n",
      "File \u001b[1;32mc:\\Users\\filou\\anaconda3\\envs\\dashcanvas\\lib\\site-packages\\sqlalchemy\\engine\\base.py:96\u001b[0m, in \u001b[0;36mConnection.__init__\u001b[1;34m(self, engine, connection, close_with_result, _branch_from, _execution_options, _dispatch, _has_events, _allow_revalidate)\u001b[0m\n\u001b[0;32m     91\u001b[0m     \u001b[39mself\u001b[39m\u001b[39m.\u001b[39m_has_events \u001b[39m=\u001b[39m _branch_from\u001b[39m.\u001b[39m_has_events\n\u001b[0;32m     92\u001b[0m \u001b[39melse\u001b[39;00m:\n\u001b[0;32m     93\u001b[0m     \u001b[39mself\u001b[39m\u001b[39m.\u001b[39m_dbapi_connection \u001b[39m=\u001b[39m (\n\u001b[0;32m     94\u001b[0m         connection\n\u001b[0;32m     95\u001b[0m         \u001b[39mif\u001b[39;00m connection \u001b[39mis\u001b[39;00m \u001b[39mnot\u001b[39;00m \u001b[39mNone\u001b[39;00m\n\u001b[1;32m---> 96\u001b[0m         \u001b[39melse\u001b[39;00m engine\u001b[39m.\u001b[39;49mraw_connection()\n\u001b[0;32m     97\u001b[0m     )\n\u001b[0;32m     99\u001b[0m     \u001b[39mself\u001b[39m\u001b[39m.\u001b[39m_transaction \u001b[39m=\u001b[39m \u001b[39mself\u001b[39m\u001b[39m.\u001b[39m_nested_transaction \u001b[39m=\u001b[39m \u001b[39mNone\u001b[39;00m\n\u001b[0;32m    100\u001b[0m     \u001b[39mself\u001b[39m\u001b[39m.\u001b[39m__savepoint_seq \u001b[39m=\u001b[39m \u001b[39m0\u001b[39m\n",
      "File \u001b[1;32mc:\\Users\\filou\\anaconda3\\envs\\dashcanvas\\lib\\site-packages\\sqlalchemy\\engine\\base.py:3394\u001b[0m, in \u001b[0;36mEngine.raw_connection\u001b[1;34m(self, _connection)\u001b[0m\n\u001b[0;32m   3372\u001b[0m \u001b[39mdef\u001b[39;00m \u001b[39mraw_connection\u001b[39m(\u001b[39mself\u001b[39m, _connection\u001b[39m=\u001b[39m\u001b[39mNone\u001b[39;00m):\n\u001b[0;32m   3373\u001b[0m     \u001b[39m\"\"\"Return a \"raw\" DBAPI connection from the connection pool.\u001b[39;00m\n\u001b[0;32m   3374\u001b[0m \n\u001b[0;32m   3375\u001b[0m \u001b[39m    The returned object is a proxied version of the DBAPI\u001b[39;00m\n\u001b[1;32m   (...)\u001b[0m\n\u001b[0;32m   3392\u001b[0m \n\u001b[0;32m   3393\u001b[0m \u001b[39m    \"\"\"\u001b[39;00m\n\u001b[1;32m-> 3394\u001b[0m     \u001b[39mreturn\u001b[39;00m \u001b[39mself\u001b[39;49m\u001b[39m.\u001b[39;49m_wrap_pool_connect(\u001b[39mself\u001b[39;49m\u001b[39m.\u001b[39;49mpool\u001b[39m.\u001b[39;49mconnect, _connection)\n",
      "File \u001b[1;32mc:\\Users\\filou\\anaconda3\\envs\\dashcanvas\\lib\\site-packages\\sqlalchemy\\engine\\base.py:3364\u001b[0m, in \u001b[0;36mEngine._wrap_pool_connect\u001b[1;34m(self, fn, connection)\u001b[0m\n\u001b[0;32m   3362\u001b[0m \u001b[39mexcept\u001b[39;00m dialect\u001b[39m.\u001b[39mdbapi\u001b[39m.\u001b[39mError \u001b[39mas\u001b[39;00m e:\n\u001b[0;32m   3363\u001b[0m     \u001b[39mif\u001b[39;00m connection \u001b[39mis\u001b[39;00m \u001b[39mNone\u001b[39;00m:\n\u001b[1;32m-> 3364\u001b[0m         Connection\u001b[39m.\u001b[39;49m_handle_dbapi_exception_noconnection(\n\u001b[0;32m   3365\u001b[0m             e, dialect, \u001b[39mself\u001b[39;49m\n\u001b[0;32m   3366\u001b[0m         )\n\u001b[0;32m   3367\u001b[0m     \u001b[39melse\u001b[39;00m:\n\u001b[0;32m   3368\u001b[0m         util\u001b[39m.\u001b[39mraise_(\n\u001b[0;32m   3369\u001b[0m             sys\u001b[39m.\u001b[39mexc_info()[\u001b[39m1\u001b[39m], with_traceback\u001b[39m=\u001b[39msys\u001b[39m.\u001b[39mexc_info()[\u001b[39m2\u001b[39m]\n\u001b[0;32m   3370\u001b[0m         )\n",
      "File \u001b[1;32mc:\\Users\\filou\\anaconda3\\envs\\dashcanvas\\lib\\site-packages\\sqlalchemy\\engine\\base.py:2198\u001b[0m, in \u001b[0;36mConnection._handle_dbapi_exception_noconnection\u001b[1;34m(cls, e, dialect, engine)\u001b[0m\n\u001b[0;32m   2196\u001b[0m     util\u001b[39m.\u001b[39mraise_(newraise, with_traceback\u001b[39m=\u001b[39mexc_info[\u001b[39m2\u001b[39m], from_\u001b[39m=\u001b[39me)\n\u001b[0;32m   2197\u001b[0m \u001b[39melif\u001b[39;00m should_wrap:\n\u001b[1;32m-> 2198\u001b[0m     util\u001b[39m.\u001b[39;49mraise_(\n\u001b[0;32m   2199\u001b[0m         sqlalchemy_exception, with_traceback\u001b[39m=\u001b[39;49mexc_info[\u001b[39m2\u001b[39;49m], from_\u001b[39m=\u001b[39;49me\n\u001b[0;32m   2200\u001b[0m     )\n\u001b[0;32m   2201\u001b[0m \u001b[39melse\u001b[39;00m:\n\u001b[0;32m   2202\u001b[0m     util\u001b[39m.\u001b[39mraise_(exc_info[\u001b[39m1\u001b[39m], with_traceback\u001b[39m=\u001b[39mexc_info[\u001b[39m2\u001b[39m])\n",
      "File \u001b[1;32mc:\\Users\\filou\\anaconda3\\envs\\dashcanvas\\lib\\site-packages\\sqlalchemy\\util\\compat.py:208\u001b[0m, in \u001b[0;36mraise_\u001b[1;34m(***failed resolving arguments***)\u001b[0m\n\u001b[0;32m    205\u001b[0m     exception\u001b[39m.\u001b[39m__cause__ \u001b[39m=\u001b[39m replace_context\n\u001b[0;32m    207\u001b[0m \u001b[39mtry\u001b[39;00m:\n\u001b[1;32m--> 208\u001b[0m     \u001b[39mraise\u001b[39;00m exception\n\u001b[0;32m    209\u001b[0m \u001b[39mfinally\u001b[39;00m:\n\u001b[0;32m    210\u001b[0m     \u001b[39m# credit to\u001b[39;00m\n\u001b[0;32m    211\u001b[0m     \u001b[39m# https://cosmicpercolator.com/2016/01/13/exception-leaks-in-python-2-and-3/\u001b[39;00m\n\u001b[0;32m    212\u001b[0m     \u001b[39m# as the __traceback__ object creates a cycle\u001b[39;00m\n\u001b[0;32m    213\u001b[0m     \u001b[39mdel\u001b[39;00m exception, replace_context, from_, with_traceback\n",
      "File \u001b[1;32mc:\\Users\\filou\\anaconda3\\envs\\dashcanvas\\lib\\site-packages\\sqlalchemy\\engine\\base.py:3361\u001b[0m, in \u001b[0;36mEngine._wrap_pool_connect\u001b[1;34m(self, fn, connection)\u001b[0m\n\u001b[0;32m   3359\u001b[0m dialect \u001b[39m=\u001b[39m \u001b[39mself\u001b[39m\u001b[39m.\u001b[39mdialect\n\u001b[0;32m   3360\u001b[0m \u001b[39mtry\u001b[39;00m:\n\u001b[1;32m-> 3361\u001b[0m     \u001b[39mreturn\u001b[39;00m fn()\n\u001b[0;32m   3362\u001b[0m \u001b[39mexcept\u001b[39;00m dialect\u001b[39m.\u001b[39mdbapi\u001b[39m.\u001b[39mError \u001b[39mas\u001b[39;00m e:\n\u001b[0;32m   3363\u001b[0m     \u001b[39mif\u001b[39;00m connection \u001b[39mis\u001b[39;00m \u001b[39mNone\u001b[39;00m:\n",
      "File \u001b[1;32mc:\\Users\\filou\\anaconda3\\envs\\dashcanvas\\lib\\site-packages\\sqlalchemy\\pool\\base.py:320\u001b[0m, in \u001b[0;36mPool.connect\u001b[1;34m(self)\u001b[0m\n\u001b[0;32m    312\u001b[0m \u001b[39mdef\u001b[39;00m \u001b[39mconnect\u001b[39m(\u001b[39mself\u001b[39m):\n\u001b[0;32m    313\u001b[0m     \u001b[39m\"\"\"Return a DBAPI connection from the pool.\u001b[39;00m\n\u001b[0;32m    314\u001b[0m \n\u001b[0;32m    315\u001b[0m \u001b[39m    The connection is instrumented such that when its\u001b[39;00m\n\u001b[1;32m   (...)\u001b[0m\n\u001b[0;32m    318\u001b[0m \n\u001b[0;32m    319\u001b[0m \u001b[39m    \"\"\"\u001b[39;00m\n\u001b[1;32m--> 320\u001b[0m     \u001b[39mreturn\u001b[39;00m _ConnectionFairy\u001b[39m.\u001b[39;49m_checkout(\u001b[39mself\u001b[39;49m)\n",
      "File \u001b[1;32mc:\\Users\\filou\\anaconda3\\envs\\dashcanvas\\lib\\site-packages\\sqlalchemy\\pool\\base.py:884\u001b[0m, in \u001b[0;36m_ConnectionFairy._checkout\u001b[1;34m(cls, pool, threadconns, fairy)\u001b[0m\n\u001b[0;32m    881\u001b[0m \u001b[39m@classmethod\u001b[39m\n\u001b[0;32m    882\u001b[0m \u001b[39mdef\u001b[39;00m \u001b[39m_checkout\u001b[39m(\u001b[39mcls\u001b[39m, pool, threadconns\u001b[39m=\u001b[39m\u001b[39mNone\u001b[39;00m, fairy\u001b[39m=\u001b[39m\u001b[39mNone\u001b[39;00m):\n\u001b[0;32m    883\u001b[0m     \u001b[39mif\u001b[39;00m \u001b[39mnot\u001b[39;00m fairy:\n\u001b[1;32m--> 884\u001b[0m         fairy \u001b[39m=\u001b[39m _ConnectionRecord\u001b[39m.\u001b[39;49mcheckout(pool)\n\u001b[0;32m    886\u001b[0m         fairy\u001b[39m.\u001b[39m_pool \u001b[39m=\u001b[39m pool\n\u001b[0;32m    887\u001b[0m         fairy\u001b[39m.\u001b[39m_counter \u001b[39m=\u001b[39m \u001b[39m0\u001b[39m\n",
      "File \u001b[1;32mc:\\Users\\filou\\anaconda3\\envs\\dashcanvas\\lib\\site-packages\\sqlalchemy\\pool\\base.py:486\u001b[0m, in \u001b[0;36m_ConnectionRecord.checkout\u001b[1;34m(cls, pool)\u001b[0m\n\u001b[0;32m    484\u001b[0m \u001b[39m@classmethod\u001b[39m\n\u001b[0;32m    485\u001b[0m \u001b[39mdef\u001b[39;00m \u001b[39mcheckout\u001b[39m(\u001b[39mcls\u001b[39m, pool):\n\u001b[1;32m--> 486\u001b[0m     rec \u001b[39m=\u001b[39m pool\u001b[39m.\u001b[39;49m_do_get()\n\u001b[0;32m    487\u001b[0m     \u001b[39mtry\u001b[39;00m:\n\u001b[0;32m    488\u001b[0m         dbapi_connection \u001b[39m=\u001b[39m rec\u001b[39m.\u001b[39mget_connection()\n",
      "File \u001b[1;32mc:\\Users\\filou\\anaconda3\\envs\\dashcanvas\\lib\\site-packages\\sqlalchemy\\pool\\impl.py:145\u001b[0m, in \u001b[0;36mQueuePool._do_get\u001b[1;34m(self)\u001b[0m\n\u001b[0;32m    143\u001b[0m         \u001b[39mreturn\u001b[39;00m \u001b[39mself\u001b[39m\u001b[39m.\u001b[39m_create_connection()\n\u001b[0;32m    144\u001b[0m     \u001b[39mexcept\u001b[39;00m:\n\u001b[1;32m--> 145\u001b[0m         \u001b[39mwith\u001b[39;00m util\u001b[39m.\u001b[39msafe_reraise():\n\u001b[0;32m    146\u001b[0m             \u001b[39mself\u001b[39m\u001b[39m.\u001b[39m_dec_overflow()\n\u001b[0;32m    147\u001b[0m \u001b[39melse\u001b[39;00m:\n",
      "File \u001b[1;32mc:\\Users\\filou\\anaconda3\\envs\\dashcanvas\\lib\\site-packages\\sqlalchemy\\util\\langhelpers.py:70\u001b[0m, in \u001b[0;36msafe_reraise.__exit__\u001b[1;34m(self, type_, value, traceback)\u001b[0m\n\u001b[0;32m     68\u001b[0m     \u001b[39mself\u001b[39m\u001b[39m.\u001b[39m_exc_info \u001b[39m=\u001b[39m \u001b[39mNone\u001b[39;00m  \u001b[39m# remove potential circular references\u001b[39;00m\n\u001b[0;32m     69\u001b[0m     \u001b[39mif\u001b[39;00m \u001b[39mnot\u001b[39;00m \u001b[39mself\u001b[39m\u001b[39m.\u001b[39mwarn_only:\n\u001b[1;32m---> 70\u001b[0m         compat\u001b[39m.\u001b[39;49mraise_(\n\u001b[0;32m     71\u001b[0m             exc_value,\n\u001b[0;32m     72\u001b[0m             with_traceback\u001b[39m=\u001b[39;49mexc_tb,\n\u001b[0;32m     73\u001b[0m         )\n\u001b[0;32m     74\u001b[0m \u001b[39melse\u001b[39;00m:\n\u001b[0;32m     75\u001b[0m     \u001b[39mif\u001b[39;00m \u001b[39mnot\u001b[39;00m compat\u001b[39m.\u001b[39mpy3k \u001b[39mand\u001b[39;00m \u001b[39mself\u001b[39m\u001b[39m.\u001b[39m_exc_info \u001b[39mand\u001b[39;00m \u001b[39mself\u001b[39m\u001b[39m.\u001b[39m_exc_info[\u001b[39m1\u001b[39m]:\n\u001b[0;32m     76\u001b[0m         \u001b[39m# emulate Py3K's behavior of telling us when an exception\u001b[39;00m\n\u001b[0;32m     77\u001b[0m         \u001b[39m# occurs in an exception handler.\u001b[39;00m\n",
      "File \u001b[1;32mc:\\Users\\filou\\anaconda3\\envs\\dashcanvas\\lib\\site-packages\\sqlalchemy\\util\\compat.py:208\u001b[0m, in \u001b[0;36mraise_\u001b[1;34m(***failed resolving arguments***)\u001b[0m\n\u001b[0;32m    205\u001b[0m     exception\u001b[39m.\u001b[39m__cause__ \u001b[39m=\u001b[39m replace_context\n\u001b[0;32m    207\u001b[0m \u001b[39mtry\u001b[39;00m:\n\u001b[1;32m--> 208\u001b[0m     \u001b[39mraise\u001b[39;00m exception\n\u001b[0;32m    209\u001b[0m \u001b[39mfinally\u001b[39;00m:\n\u001b[0;32m    210\u001b[0m     \u001b[39m# credit to\u001b[39;00m\n\u001b[0;32m    211\u001b[0m     \u001b[39m# https://cosmicpercolator.com/2016/01/13/exception-leaks-in-python-2-and-3/\u001b[39;00m\n\u001b[0;32m    212\u001b[0m     \u001b[39m# as the __traceback__ object creates a cycle\u001b[39;00m\n\u001b[0;32m    213\u001b[0m     \u001b[39mdel\u001b[39;00m exception, replace_context, from_, with_traceback\n",
      "File \u001b[1;32mc:\\Users\\filou\\anaconda3\\envs\\dashcanvas\\lib\\site-packages\\sqlalchemy\\pool\\impl.py:143\u001b[0m, in \u001b[0;36mQueuePool._do_get\u001b[1;34m(self)\u001b[0m\n\u001b[0;32m    141\u001b[0m \u001b[39mif\u001b[39;00m \u001b[39mself\u001b[39m\u001b[39m.\u001b[39m_inc_overflow():\n\u001b[0;32m    142\u001b[0m     \u001b[39mtry\u001b[39;00m:\n\u001b[1;32m--> 143\u001b[0m         \u001b[39mreturn\u001b[39;00m \u001b[39mself\u001b[39;49m\u001b[39m.\u001b[39;49m_create_connection()\n\u001b[0;32m    144\u001b[0m     \u001b[39mexcept\u001b[39;00m:\n\u001b[0;32m    145\u001b[0m         \u001b[39mwith\u001b[39;00m util\u001b[39m.\u001b[39msafe_reraise():\n",
      "File \u001b[1;32mc:\\Users\\filou\\anaconda3\\envs\\dashcanvas\\lib\\site-packages\\sqlalchemy\\pool\\base.py:266\u001b[0m, in \u001b[0;36mPool._create_connection\u001b[1;34m(self)\u001b[0m\n\u001b[0;32m    263\u001b[0m \u001b[39mdef\u001b[39;00m \u001b[39m_create_connection\u001b[39m(\u001b[39mself\u001b[39m):\n\u001b[0;32m    264\u001b[0m     \u001b[39m\"\"\"Called by subclasses to create a new ConnectionRecord.\"\"\"\u001b[39;00m\n\u001b[1;32m--> 266\u001b[0m     \u001b[39mreturn\u001b[39;00m _ConnectionRecord(\u001b[39mself\u001b[39;49m)\n",
      "File \u001b[1;32mc:\\Users\\filou\\anaconda3\\envs\\dashcanvas\\lib\\site-packages\\sqlalchemy\\pool\\base.py:381\u001b[0m, in \u001b[0;36m_ConnectionRecord.__init__\u001b[1;34m(self, pool, connect)\u001b[0m\n\u001b[0;32m    379\u001b[0m \u001b[39mself\u001b[39m\u001b[39m.\u001b[39m__pool \u001b[39m=\u001b[39m pool\n\u001b[0;32m    380\u001b[0m \u001b[39mif\u001b[39;00m connect:\n\u001b[1;32m--> 381\u001b[0m     \u001b[39mself\u001b[39;49m\u001b[39m.\u001b[39;49m__connect()\n\u001b[0;32m    382\u001b[0m \u001b[39mself\u001b[39m\u001b[39m.\u001b[39mfinalize_callback \u001b[39m=\u001b[39m deque()\n",
      "File \u001b[1;32mc:\\Users\\filou\\anaconda3\\envs\\dashcanvas\\lib\\site-packages\\sqlalchemy\\pool\\base.py:677\u001b[0m, in \u001b[0;36m_ConnectionRecord.__connect\u001b[1;34m(self)\u001b[0m\n\u001b[0;32m    675\u001b[0m     \u001b[39mself\u001b[39m\u001b[39m.\u001b[39mfresh \u001b[39m=\u001b[39m \u001b[39mTrue\u001b[39;00m\n\u001b[0;32m    676\u001b[0m \u001b[39mexcept\u001b[39;00m \u001b[39mException\u001b[39;00m \u001b[39mas\u001b[39;00m e:\n\u001b[1;32m--> 677\u001b[0m     \u001b[39mwith\u001b[39;00m util\u001b[39m.\u001b[39msafe_reraise():\n\u001b[0;32m    678\u001b[0m         pool\u001b[39m.\u001b[39mlogger\u001b[39m.\u001b[39mdebug(\u001b[39m\"\u001b[39m\u001b[39mError on connect(): \u001b[39m\u001b[39m%s\u001b[39;00m\u001b[39m\"\u001b[39m, e)\n\u001b[0;32m    679\u001b[0m \u001b[39melse\u001b[39;00m:\n\u001b[0;32m    680\u001b[0m     \u001b[39m# in SQLAlchemy 1.4 the first_connect event is not used by\u001b[39;00m\n\u001b[0;32m    681\u001b[0m     \u001b[39m# the engine, so this will usually not be set\u001b[39;00m\n",
      "File \u001b[1;32mc:\\Users\\filou\\anaconda3\\envs\\dashcanvas\\lib\\site-packages\\sqlalchemy\\util\\langhelpers.py:70\u001b[0m, in \u001b[0;36msafe_reraise.__exit__\u001b[1;34m(self, type_, value, traceback)\u001b[0m\n\u001b[0;32m     68\u001b[0m     \u001b[39mself\u001b[39m\u001b[39m.\u001b[39m_exc_info \u001b[39m=\u001b[39m \u001b[39mNone\u001b[39;00m  \u001b[39m# remove potential circular references\u001b[39;00m\n\u001b[0;32m     69\u001b[0m     \u001b[39mif\u001b[39;00m \u001b[39mnot\u001b[39;00m \u001b[39mself\u001b[39m\u001b[39m.\u001b[39mwarn_only:\n\u001b[1;32m---> 70\u001b[0m         compat\u001b[39m.\u001b[39;49mraise_(\n\u001b[0;32m     71\u001b[0m             exc_value,\n\u001b[0;32m     72\u001b[0m             with_traceback\u001b[39m=\u001b[39;49mexc_tb,\n\u001b[0;32m     73\u001b[0m         )\n\u001b[0;32m     74\u001b[0m \u001b[39melse\u001b[39;00m:\n\u001b[0;32m     75\u001b[0m     \u001b[39mif\u001b[39;00m \u001b[39mnot\u001b[39;00m compat\u001b[39m.\u001b[39mpy3k \u001b[39mand\u001b[39;00m \u001b[39mself\u001b[39m\u001b[39m.\u001b[39m_exc_info \u001b[39mand\u001b[39;00m \u001b[39mself\u001b[39m\u001b[39m.\u001b[39m_exc_info[\u001b[39m1\u001b[39m]:\n\u001b[0;32m     76\u001b[0m         \u001b[39m# emulate Py3K's behavior of telling us when an exception\u001b[39;00m\n\u001b[0;32m     77\u001b[0m         \u001b[39m# occurs in an exception handler.\u001b[39;00m\n",
      "File \u001b[1;32mc:\\Users\\filou\\anaconda3\\envs\\dashcanvas\\lib\\site-packages\\sqlalchemy\\util\\compat.py:208\u001b[0m, in \u001b[0;36mraise_\u001b[1;34m(***failed resolving arguments***)\u001b[0m\n\u001b[0;32m    205\u001b[0m     exception\u001b[39m.\u001b[39m__cause__ \u001b[39m=\u001b[39m replace_context\n\u001b[0;32m    207\u001b[0m \u001b[39mtry\u001b[39;00m:\n\u001b[1;32m--> 208\u001b[0m     \u001b[39mraise\u001b[39;00m exception\n\u001b[0;32m    209\u001b[0m \u001b[39mfinally\u001b[39;00m:\n\u001b[0;32m    210\u001b[0m     \u001b[39m# credit to\u001b[39;00m\n\u001b[0;32m    211\u001b[0m     \u001b[39m# https://cosmicpercolator.com/2016/01/13/exception-leaks-in-python-2-and-3/\u001b[39;00m\n\u001b[0;32m    212\u001b[0m     \u001b[39m# as the __traceback__ object creates a cycle\u001b[39;00m\n\u001b[0;32m    213\u001b[0m     \u001b[39mdel\u001b[39;00m exception, replace_context, from_, with_traceback\n",
      "File \u001b[1;32mc:\\Users\\filou\\anaconda3\\envs\\dashcanvas\\lib\\site-packages\\sqlalchemy\\pool\\base.py:673\u001b[0m, in \u001b[0;36m_ConnectionRecord.__connect\u001b[1;34m(self)\u001b[0m\n\u001b[0;32m    671\u001b[0m \u001b[39mtry\u001b[39;00m:\n\u001b[0;32m    672\u001b[0m     \u001b[39mself\u001b[39m\u001b[39m.\u001b[39mstarttime \u001b[39m=\u001b[39m time\u001b[39m.\u001b[39mtime()\n\u001b[1;32m--> 673\u001b[0m     \u001b[39mself\u001b[39m\u001b[39m.\u001b[39mdbapi_connection \u001b[39m=\u001b[39m connection \u001b[39m=\u001b[39m pool\u001b[39m.\u001b[39;49m_invoke_creator(\u001b[39mself\u001b[39;49m)\n\u001b[0;32m    674\u001b[0m     pool\u001b[39m.\u001b[39mlogger\u001b[39m.\u001b[39mdebug(\u001b[39m\"\u001b[39m\u001b[39mCreated new connection \u001b[39m\u001b[39m%r\u001b[39;00m\u001b[39m\"\u001b[39m, connection)\n\u001b[0;32m    675\u001b[0m     \u001b[39mself\u001b[39m\u001b[39m.\u001b[39mfresh \u001b[39m=\u001b[39m \u001b[39mTrue\u001b[39;00m\n",
      "File \u001b[1;32mc:\\Users\\filou\\anaconda3\\envs\\dashcanvas\\lib\\site-packages\\sqlalchemy\\engine\\create.py:578\u001b[0m, in \u001b[0;36mcreate_engine.<locals>.connect\u001b[1;34m(connection_record)\u001b[0m\n\u001b[0;32m    576\u001b[0m         \u001b[39mif\u001b[39;00m connection \u001b[39mis\u001b[39;00m \u001b[39mnot\u001b[39;00m \u001b[39mNone\u001b[39;00m:\n\u001b[0;32m    577\u001b[0m             \u001b[39mreturn\u001b[39;00m connection\n\u001b[1;32m--> 578\u001b[0m \u001b[39mreturn\u001b[39;00m dialect\u001b[39m.\u001b[39mconnect(\u001b[39m*\u001b[39mcargs, \u001b[39m*\u001b[39m\u001b[39m*\u001b[39mcparams)\n",
      "File \u001b[1;32mc:\\Users\\filou\\anaconda3\\envs\\dashcanvas\\lib\\site-packages\\sqlalchemy\\engine\\default.py:598\u001b[0m, in \u001b[0;36mDefaultDialect.connect\u001b[1;34m(self, *cargs, **cparams)\u001b[0m\n\u001b[0;32m    596\u001b[0m \u001b[39mdef\u001b[39;00m \u001b[39mconnect\u001b[39m(\u001b[39mself\u001b[39m, \u001b[39m*\u001b[39mcargs, \u001b[39m*\u001b[39m\u001b[39m*\u001b[39mcparams):\n\u001b[0;32m    597\u001b[0m     \u001b[39m# inherits the docstring from interfaces.Dialect.connect\u001b[39;00m\n\u001b[1;32m--> 598\u001b[0m     \u001b[39mreturn\u001b[39;00m \u001b[39mself\u001b[39m\u001b[39m.\u001b[39mdbapi\u001b[39m.\u001b[39mconnect(\u001b[39m*\u001b[39mcargs, \u001b[39m*\u001b[39m\u001b[39m*\u001b[39mcparams)\n",
      "File \u001b[1;32mc:\\Users\\filou\\anaconda3\\envs\\dashcanvas\\lib\\site-packages\\pymysql\\connections.py:353\u001b[0m, in \u001b[0;36mConnection.__init__\u001b[1;34m(self, user, password, host, database, unix_socket, port, charset, sql_mode, read_default_file, conv, use_unicode, client_flag, cursorclass, init_command, connect_timeout, read_default_group, autocommit, local_infile, max_allowed_packet, defer_connect, auth_plugin_map, read_timeout, write_timeout, bind_address, binary_prefix, program_name, server_public_key, ssl, ssl_ca, ssl_cert, ssl_disabled, ssl_key, ssl_verify_cert, ssl_verify_identity, compress, named_pipe, passwd, db)\u001b[0m\n\u001b[0;32m    351\u001b[0m     \u001b[39mself\u001b[39m\u001b[39m.\u001b[39m_sock \u001b[39m=\u001b[39m \u001b[39mNone\u001b[39;00m\n\u001b[0;32m    352\u001b[0m \u001b[39melse\u001b[39;00m:\n\u001b[1;32m--> 353\u001b[0m     \u001b[39mself\u001b[39;49m\u001b[39m.\u001b[39;49mconnect()\n",
      "File \u001b[1;32mc:\\Users\\filou\\anaconda3\\envs\\dashcanvas\\lib\\site-packages\\pymysql\\connections.py:664\u001b[0m, in \u001b[0;36mConnection.connect\u001b[1;34m(self, sock)\u001b[0m\n\u001b[0;32m    662\u001b[0m     \u001b[39mif\u001b[39;00m DEBUG:\n\u001b[0;32m    663\u001b[0m         \u001b[39mprint\u001b[39m(exc\u001b[39m.\u001b[39mtraceback)\n\u001b[1;32m--> 664\u001b[0m     \u001b[39mraise\u001b[39;00m exc\n\u001b[0;32m    666\u001b[0m \u001b[39m# If e is neither DatabaseError or IOError, It's a bug.\u001b[39;00m\n\u001b[0;32m    667\u001b[0m \u001b[39m# But raising AssertionError hides original error.\u001b[39;00m\n\u001b[0;32m    668\u001b[0m \u001b[39m# So just reraise it.\u001b[39;00m\n\u001b[0;32m    669\u001b[0m \u001b[39mraise\u001b[39;00m\n",
      "\u001b[1;31mOperationalError\u001b[0m: (pymysql.err.OperationalError) (2003, \"Can't connect to MySQL server on 'localhost' ([WinError 10061] Aucune connexion n’a pu être établie car l’ordinateur cible l’a expressément refusée)\")\n(Background on this error at: https://sqlalche.me/e/14/e3q8)"
     ]
    }
   ],
   "source": [
    "con = engine.connect()"
   ]
  },
  {
   "cell_type": "code",
   "execution_count": null,
   "metadata": {},
   "outputs": [],
   "source": [
    "con."
   ]
  },
  {
   "cell_type": "code",
   "execution_count": 15,
   "metadata": {},
   "outputs": [
    {
     "ename": "OperationalError",
     "evalue": "(pymysql.err.OperationalError) (2003, \"Can't connect to MySQL server on 'localhost' ([WinError 10061] Aucune connexion n’a pu être établie car l’ordinateur cible l’a expressément refusée)\")\n(Background on this error at: https://sqlalche.me/e/14/e3q8)",
     "output_type": "error",
     "traceback": [
      "\u001b[1;31m---------------------------------------------------------------------------\u001b[0m",
      "\u001b[1;31mConnectionRefusedError\u001b[0m                    Traceback (most recent call last)",
      "File \u001b[1;32mc:\\Users\\filou\\anaconda3\\envs\\dashcanvas\\lib\\site-packages\\pymysql\\connections.py:613\u001b[0m, in \u001b[0;36mConnection.connect\u001b[1;34m(self, sock)\u001b[0m\n\u001b[0;32m    612\u001b[0m \u001b[39mtry\u001b[39;00m:\n\u001b[1;32m--> 613\u001b[0m     sock \u001b[39m=\u001b[39m socket\u001b[39m.\u001b[39mcreate_connection(\n\u001b[0;32m    614\u001b[0m         (\u001b[39mself\u001b[39m\u001b[39m.\u001b[39mhost, \u001b[39mself\u001b[39m\u001b[39m.\u001b[39mport), \u001b[39mself\u001b[39m\u001b[39m.\u001b[39mconnect_timeout, \u001b[39m*\u001b[39m\u001b[39m*\u001b[39mkwargs\n\u001b[0;32m    615\u001b[0m     )\n\u001b[0;32m    616\u001b[0m     \u001b[39mbreak\u001b[39;00m\n",
      "File \u001b[1;32mc:\\Users\\filou\\anaconda3\\envs\\dashcanvas\\lib\\socket.py:845\u001b[0m, in \u001b[0;36mcreate_connection\u001b[1;34m(address, timeout, source_address)\u001b[0m\n\u001b[0;32m    844\u001b[0m \u001b[39mtry\u001b[39;00m:\n\u001b[1;32m--> 845\u001b[0m     \u001b[39mraise\u001b[39;00m err\n\u001b[0;32m    846\u001b[0m \u001b[39mfinally\u001b[39;00m:\n\u001b[0;32m    847\u001b[0m     \u001b[39m# Break explicitly a reference cycle\u001b[39;00m\n",
      "File \u001b[1;32mc:\\Users\\filou\\anaconda3\\envs\\dashcanvas\\lib\\socket.py:833\u001b[0m, in \u001b[0;36mcreate_connection\u001b[1;34m(address, timeout, source_address)\u001b[0m\n\u001b[0;32m    832\u001b[0m     sock\u001b[39m.\u001b[39mbind(source_address)\n\u001b[1;32m--> 833\u001b[0m sock\u001b[39m.\u001b[39;49mconnect(sa)\n\u001b[0;32m    834\u001b[0m \u001b[39m# Break explicitly a reference cycle\u001b[39;00m\n",
      "\u001b[1;31mConnectionRefusedError\u001b[0m: [WinError 10061] Aucune connexion n’a pu être établie car l’ordinateur cible l’a expressément refusée",
      "\nDuring handling of the above exception, another exception occurred:\n",
      "\u001b[1;31mOperationalError\u001b[0m                          Traceback (most recent call last)",
      "File \u001b[1;32mc:\\Users\\filou\\anaconda3\\envs\\dashcanvas\\lib\\site-packages\\sqlalchemy\\engine\\base.py:3361\u001b[0m, in \u001b[0;36mEngine._wrap_pool_connect\u001b[1;34m(self, fn, connection)\u001b[0m\n\u001b[0;32m   3360\u001b[0m \u001b[39mtry\u001b[39;00m:\n\u001b[1;32m-> 3361\u001b[0m     \u001b[39mreturn\u001b[39;00m fn()\n\u001b[0;32m   3362\u001b[0m \u001b[39mexcept\u001b[39;00m dialect\u001b[39m.\u001b[39mdbapi\u001b[39m.\u001b[39mError \u001b[39mas\u001b[39;00m e:\n",
      "File \u001b[1;32mc:\\Users\\filou\\anaconda3\\envs\\dashcanvas\\lib\\site-packages\\sqlalchemy\\pool\\base.py:320\u001b[0m, in \u001b[0;36mPool.connect\u001b[1;34m(self)\u001b[0m\n\u001b[0;32m    313\u001b[0m \u001b[39m\"\"\"Return a DBAPI connection from the pool.\u001b[39;00m\n\u001b[0;32m    314\u001b[0m \n\u001b[0;32m    315\u001b[0m \u001b[39mThe connection is instrumented such that when its\u001b[39;00m\n\u001b[1;32m   (...)\u001b[0m\n\u001b[0;32m    318\u001b[0m \n\u001b[0;32m    319\u001b[0m \u001b[39m\"\"\"\u001b[39;00m\n\u001b[1;32m--> 320\u001b[0m \u001b[39mreturn\u001b[39;00m _ConnectionFairy\u001b[39m.\u001b[39;49m_checkout(\u001b[39mself\u001b[39;49m)\n",
      "File \u001b[1;32mc:\\Users\\filou\\anaconda3\\envs\\dashcanvas\\lib\\site-packages\\sqlalchemy\\pool\\base.py:884\u001b[0m, in \u001b[0;36m_ConnectionFairy._checkout\u001b[1;34m(cls, pool, threadconns, fairy)\u001b[0m\n\u001b[0;32m    883\u001b[0m \u001b[39mif\u001b[39;00m \u001b[39mnot\u001b[39;00m fairy:\n\u001b[1;32m--> 884\u001b[0m     fairy \u001b[39m=\u001b[39m _ConnectionRecord\u001b[39m.\u001b[39;49mcheckout(pool)\n\u001b[0;32m    886\u001b[0m     fairy\u001b[39m.\u001b[39m_pool \u001b[39m=\u001b[39m pool\n",
      "File \u001b[1;32mc:\\Users\\filou\\anaconda3\\envs\\dashcanvas\\lib\\site-packages\\sqlalchemy\\pool\\base.py:486\u001b[0m, in \u001b[0;36m_ConnectionRecord.checkout\u001b[1;34m(cls, pool)\u001b[0m\n\u001b[0;32m    484\u001b[0m \u001b[39m@classmethod\u001b[39m\n\u001b[0;32m    485\u001b[0m \u001b[39mdef\u001b[39;00m \u001b[39mcheckout\u001b[39m(\u001b[39mcls\u001b[39m, pool):\n\u001b[1;32m--> 486\u001b[0m     rec \u001b[39m=\u001b[39m pool\u001b[39m.\u001b[39;49m_do_get()\n\u001b[0;32m    487\u001b[0m     \u001b[39mtry\u001b[39;00m:\n",
      "File \u001b[1;32mc:\\Users\\filou\\anaconda3\\envs\\dashcanvas\\lib\\site-packages\\sqlalchemy\\pool\\impl.py:145\u001b[0m, in \u001b[0;36mQueuePool._do_get\u001b[1;34m(self)\u001b[0m\n\u001b[0;32m    144\u001b[0m \u001b[39mexcept\u001b[39;00m:\n\u001b[1;32m--> 145\u001b[0m     \u001b[39mwith\u001b[39;00m util\u001b[39m.\u001b[39msafe_reraise():\n\u001b[0;32m    146\u001b[0m         \u001b[39mself\u001b[39m\u001b[39m.\u001b[39m_dec_overflow()\n",
      "File \u001b[1;32mc:\\Users\\filou\\anaconda3\\envs\\dashcanvas\\lib\\site-packages\\sqlalchemy\\util\\langhelpers.py:70\u001b[0m, in \u001b[0;36msafe_reraise.__exit__\u001b[1;34m(self, type_, value, traceback)\u001b[0m\n\u001b[0;32m     69\u001b[0m     \u001b[39mif\u001b[39;00m \u001b[39mnot\u001b[39;00m \u001b[39mself\u001b[39m\u001b[39m.\u001b[39mwarn_only:\n\u001b[1;32m---> 70\u001b[0m         compat\u001b[39m.\u001b[39;49mraise_(\n\u001b[0;32m     71\u001b[0m             exc_value,\n\u001b[0;32m     72\u001b[0m             with_traceback\u001b[39m=\u001b[39;49mexc_tb,\n\u001b[0;32m     73\u001b[0m         )\n\u001b[0;32m     74\u001b[0m \u001b[39melse\u001b[39;00m:\n",
      "File \u001b[1;32mc:\\Users\\filou\\anaconda3\\envs\\dashcanvas\\lib\\site-packages\\sqlalchemy\\util\\compat.py:208\u001b[0m, in \u001b[0;36mraise_\u001b[1;34m(***failed resolving arguments***)\u001b[0m\n\u001b[0;32m    207\u001b[0m \u001b[39mtry\u001b[39;00m:\n\u001b[1;32m--> 208\u001b[0m     \u001b[39mraise\u001b[39;00m exception\n\u001b[0;32m    209\u001b[0m \u001b[39mfinally\u001b[39;00m:\n\u001b[0;32m    210\u001b[0m     \u001b[39m# credit to\u001b[39;00m\n\u001b[0;32m    211\u001b[0m     \u001b[39m# https://cosmicpercolator.com/2016/01/13/exception-leaks-in-python-2-and-3/\u001b[39;00m\n\u001b[0;32m    212\u001b[0m     \u001b[39m# as the __traceback__ object creates a cycle\u001b[39;00m\n",
      "File \u001b[1;32mc:\\Users\\filou\\anaconda3\\envs\\dashcanvas\\lib\\site-packages\\sqlalchemy\\pool\\impl.py:143\u001b[0m, in \u001b[0;36mQueuePool._do_get\u001b[1;34m(self)\u001b[0m\n\u001b[0;32m    142\u001b[0m \u001b[39mtry\u001b[39;00m:\n\u001b[1;32m--> 143\u001b[0m     \u001b[39mreturn\u001b[39;00m \u001b[39mself\u001b[39;49m\u001b[39m.\u001b[39;49m_create_connection()\n\u001b[0;32m    144\u001b[0m \u001b[39mexcept\u001b[39;00m:\n",
      "File \u001b[1;32mc:\\Users\\filou\\anaconda3\\envs\\dashcanvas\\lib\\site-packages\\sqlalchemy\\pool\\base.py:266\u001b[0m, in \u001b[0;36mPool._create_connection\u001b[1;34m(self)\u001b[0m\n\u001b[0;32m    264\u001b[0m \u001b[39m\"\"\"Called by subclasses to create a new ConnectionRecord.\"\"\"\u001b[39;00m\n\u001b[1;32m--> 266\u001b[0m \u001b[39mreturn\u001b[39;00m _ConnectionRecord(\u001b[39mself\u001b[39;49m)\n",
      "File \u001b[1;32mc:\\Users\\filou\\anaconda3\\envs\\dashcanvas\\lib\\site-packages\\sqlalchemy\\pool\\base.py:381\u001b[0m, in \u001b[0;36m_ConnectionRecord.__init__\u001b[1;34m(self, pool, connect)\u001b[0m\n\u001b[0;32m    380\u001b[0m \u001b[39mif\u001b[39;00m connect:\n\u001b[1;32m--> 381\u001b[0m     \u001b[39mself\u001b[39;49m\u001b[39m.\u001b[39;49m__connect()\n\u001b[0;32m    382\u001b[0m \u001b[39mself\u001b[39m\u001b[39m.\u001b[39mfinalize_callback \u001b[39m=\u001b[39m deque()\n",
      "File \u001b[1;32mc:\\Users\\filou\\anaconda3\\envs\\dashcanvas\\lib\\site-packages\\sqlalchemy\\pool\\base.py:677\u001b[0m, in \u001b[0;36m_ConnectionRecord.__connect\u001b[1;34m(self)\u001b[0m\n\u001b[0;32m    676\u001b[0m \u001b[39mexcept\u001b[39;00m \u001b[39mException\u001b[39;00m \u001b[39mas\u001b[39;00m e:\n\u001b[1;32m--> 677\u001b[0m     \u001b[39mwith\u001b[39;00m util\u001b[39m.\u001b[39msafe_reraise():\n\u001b[0;32m    678\u001b[0m         pool\u001b[39m.\u001b[39mlogger\u001b[39m.\u001b[39mdebug(\u001b[39m\"\u001b[39m\u001b[39mError on connect(): \u001b[39m\u001b[39m%s\u001b[39;00m\u001b[39m\"\u001b[39m, e)\n",
      "File \u001b[1;32mc:\\Users\\filou\\anaconda3\\envs\\dashcanvas\\lib\\site-packages\\sqlalchemy\\util\\langhelpers.py:70\u001b[0m, in \u001b[0;36msafe_reraise.__exit__\u001b[1;34m(self, type_, value, traceback)\u001b[0m\n\u001b[0;32m     69\u001b[0m     \u001b[39mif\u001b[39;00m \u001b[39mnot\u001b[39;00m \u001b[39mself\u001b[39m\u001b[39m.\u001b[39mwarn_only:\n\u001b[1;32m---> 70\u001b[0m         compat\u001b[39m.\u001b[39;49mraise_(\n\u001b[0;32m     71\u001b[0m             exc_value,\n\u001b[0;32m     72\u001b[0m             with_traceback\u001b[39m=\u001b[39;49mexc_tb,\n\u001b[0;32m     73\u001b[0m         )\n\u001b[0;32m     74\u001b[0m \u001b[39melse\u001b[39;00m:\n",
      "File \u001b[1;32mc:\\Users\\filou\\anaconda3\\envs\\dashcanvas\\lib\\site-packages\\sqlalchemy\\util\\compat.py:208\u001b[0m, in \u001b[0;36mraise_\u001b[1;34m(***failed resolving arguments***)\u001b[0m\n\u001b[0;32m    207\u001b[0m \u001b[39mtry\u001b[39;00m:\n\u001b[1;32m--> 208\u001b[0m     \u001b[39mraise\u001b[39;00m exception\n\u001b[0;32m    209\u001b[0m \u001b[39mfinally\u001b[39;00m:\n\u001b[0;32m    210\u001b[0m     \u001b[39m# credit to\u001b[39;00m\n\u001b[0;32m    211\u001b[0m     \u001b[39m# https://cosmicpercolator.com/2016/01/13/exception-leaks-in-python-2-and-3/\u001b[39;00m\n\u001b[0;32m    212\u001b[0m     \u001b[39m# as the __traceback__ object creates a cycle\u001b[39;00m\n",
      "File \u001b[1;32mc:\\Users\\filou\\anaconda3\\envs\\dashcanvas\\lib\\site-packages\\sqlalchemy\\pool\\base.py:673\u001b[0m, in \u001b[0;36m_ConnectionRecord.__connect\u001b[1;34m(self)\u001b[0m\n\u001b[0;32m    672\u001b[0m \u001b[39mself\u001b[39m\u001b[39m.\u001b[39mstarttime \u001b[39m=\u001b[39m time\u001b[39m.\u001b[39mtime()\n\u001b[1;32m--> 673\u001b[0m \u001b[39mself\u001b[39m\u001b[39m.\u001b[39mdbapi_connection \u001b[39m=\u001b[39m connection \u001b[39m=\u001b[39m pool\u001b[39m.\u001b[39;49m_invoke_creator(\u001b[39mself\u001b[39;49m)\n\u001b[0;32m    674\u001b[0m pool\u001b[39m.\u001b[39mlogger\u001b[39m.\u001b[39mdebug(\u001b[39m\"\u001b[39m\u001b[39mCreated new connection \u001b[39m\u001b[39m%r\u001b[39;00m\u001b[39m\"\u001b[39m, connection)\n",
      "File \u001b[1;32mc:\\Users\\filou\\anaconda3\\envs\\dashcanvas\\lib\\site-packages\\sqlalchemy\\engine\\create.py:578\u001b[0m, in \u001b[0;36mcreate_engine.<locals>.connect\u001b[1;34m(connection_record)\u001b[0m\n\u001b[0;32m    577\u001b[0m             \u001b[39mreturn\u001b[39;00m connection\n\u001b[1;32m--> 578\u001b[0m \u001b[39mreturn\u001b[39;00m dialect\u001b[39m.\u001b[39mconnect(\u001b[39m*\u001b[39mcargs, \u001b[39m*\u001b[39m\u001b[39m*\u001b[39mcparams)\n",
      "File \u001b[1;32mc:\\Users\\filou\\anaconda3\\envs\\dashcanvas\\lib\\site-packages\\sqlalchemy\\engine\\default.py:598\u001b[0m, in \u001b[0;36mDefaultDialect.connect\u001b[1;34m(self, *cargs, **cparams)\u001b[0m\n\u001b[0;32m    596\u001b[0m \u001b[39mdef\u001b[39;00m \u001b[39mconnect\u001b[39m(\u001b[39mself\u001b[39m, \u001b[39m*\u001b[39mcargs, \u001b[39m*\u001b[39m\u001b[39m*\u001b[39mcparams):\n\u001b[0;32m    597\u001b[0m     \u001b[39m# inherits the docstring from interfaces.Dialect.connect\u001b[39;00m\n\u001b[1;32m--> 598\u001b[0m     \u001b[39mreturn\u001b[39;00m \u001b[39mself\u001b[39m\u001b[39m.\u001b[39mdbapi\u001b[39m.\u001b[39mconnect(\u001b[39m*\u001b[39mcargs, \u001b[39m*\u001b[39m\u001b[39m*\u001b[39mcparams)\n",
      "File \u001b[1;32mc:\\Users\\filou\\anaconda3\\envs\\dashcanvas\\lib\\site-packages\\pymysql\\connections.py:353\u001b[0m, in \u001b[0;36mConnection.__init__\u001b[1;34m(self, user, password, host, database, unix_socket, port, charset, sql_mode, read_default_file, conv, use_unicode, client_flag, cursorclass, init_command, connect_timeout, read_default_group, autocommit, local_infile, max_allowed_packet, defer_connect, auth_plugin_map, read_timeout, write_timeout, bind_address, binary_prefix, program_name, server_public_key, ssl, ssl_ca, ssl_cert, ssl_disabled, ssl_key, ssl_verify_cert, ssl_verify_identity, compress, named_pipe, passwd, db)\u001b[0m\n\u001b[0;32m    352\u001b[0m \u001b[39melse\u001b[39;00m:\n\u001b[1;32m--> 353\u001b[0m     \u001b[39mself\u001b[39;49m\u001b[39m.\u001b[39;49mconnect()\n",
      "File \u001b[1;32mc:\\Users\\filou\\anaconda3\\envs\\dashcanvas\\lib\\site-packages\\pymysql\\connections.py:664\u001b[0m, in \u001b[0;36mConnection.connect\u001b[1;34m(self, sock)\u001b[0m\n\u001b[0;32m    663\u001b[0m         \u001b[39mprint\u001b[39m(exc\u001b[39m.\u001b[39mtraceback)\n\u001b[1;32m--> 664\u001b[0m     \u001b[39mraise\u001b[39;00m exc\n\u001b[0;32m    666\u001b[0m \u001b[39m# If e is neither DatabaseError or IOError, It's a bug.\u001b[39;00m\n\u001b[0;32m    667\u001b[0m \u001b[39m# But raising AssertionError hides original error.\u001b[39;00m\n\u001b[0;32m    668\u001b[0m \u001b[39m# So just reraise it.\u001b[39;00m\n",
      "\u001b[1;31mOperationalError\u001b[0m: (2003, \"Can't connect to MySQL server on 'localhost' ([WinError 10061] Aucune connexion n’a pu être établie car l’ordinateur cible l’a expressément refusée)\")",
      "\nThe above exception was the direct cause of the following exception:\n",
      "\u001b[1;31mOperationalError\u001b[0m                          Traceback (most recent call last)",
      "Cell \u001b[1;32mIn [15], line 3\u001b[0m\n\u001b[0;32m      1\u001b[0m engine \u001b[38;5;241m=\u001b[39m connect_unix_socket()\n\u001b[0;32m      2\u001b[0m metadata \u001b[38;5;241m=\u001b[39m db\u001b[38;5;241m.\u001b[39mMetaData()\n\u001b[1;32m----> 3\u001b[0m users \u001b[38;5;241m=\u001b[39m \u001b[43mdb\u001b[49m\u001b[38;5;241;43m.\u001b[39;49m\u001b[43mTable\u001b[49m\u001b[43m(\u001b[49m\u001b[38;5;124;43m'\u001b[39;49m\u001b[38;5;124;43musers\u001b[39;49m\u001b[38;5;124;43m'\u001b[39;49m\u001b[43m,\u001b[49m\u001b[43m \u001b[49m\u001b[43mmetadata\u001b[49m\u001b[43m,\u001b[49m\u001b[43m \u001b[49m\u001b[43mautoload\u001b[49m\u001b[38;5;241;43m=\u001b[39;49m\u001b[38;5;28;43;01mTrue\u001b[39;49;00m\u001b[43m,\u001b[49m\u001b[43m \u001b[49m\u001b[43mautoload_with\u001b[49m\u001b[38;5;241;43m=\u001b[39;49m\u001b[43mengine\u001b[49m\u001b[43m)\u001b[49m\n",
      "File \u001b[1;32m<string>:2\u001b[0m, in \u001b[0;36m__new__\u001b[1;34m(cls, *args, **kw)\u001b[0m\n",
      "File \u001b[1;32mc:\\Users\\filou\\anaconda3\\envs\\dashcanvas\\lib\\site-packages\\sqlalchemy\\util\\deprecations.py:309\u001b[0m, in \u001b[0;36mdeprecated_params.<locals>.decorate.<locals>.warned\u001b[1;34m(fn, *args, **kwargs)\u001b[0m\n\u001b[0;32m    302\u001b[0m     \u001b[39mif\u001b[39;00m m \u001b[39min\u001b[39;00m kwargs:\n\u001b[0;32m    303\u001b[0m         _warn_with_version(\n\u001b[0;32m    304\u001b[0m             messages[m],\n\u001b[0;32m    305\u001b[0m             versions[m],\n\u001b[0;32m    306\u001b[0m             version_warnings[m],\n\u001b[0;32m    307\u001b[0m             stacklevel\u001b[39m=\u001b[39m\u001b[39m3\u001b[39m,\n\u001b[0;32m    308\u001b[0m         )\n\u001b[1;32m--> 309\u001b[0m \u001b[39mreturn\u001b[39;00m fn(\u001b[39m*\u001b[39margs, \u001b[39m*\u001b[39m\u001b[39m*\u001b[39mkwargs)\n",
      "File \u001b[1;32mc:\\Users\\filou\\anaconda3\\envs\\dashcanvas\\lib\\site-packages\\sqlalchemy\\sql\\schema.py:616\u001b[0m, in \u001b[0;36mTable.__new__\u001b[1;34m(cls, *args, **kw)\u001b[0m\n\u001b[0;32m    614\u001b[0m     \u001b[39mreturn\u001b[39;00m table\n\u001b[0;32m    615\u001b[0m \u001b[39mexcept\u001b[39;00m \u001b[39mException\u001b[39;00m:\n\u001b[1;32m--> 616\u001b[0m     \u001b[39mwith\u001b[39;00m util\u001b[39m.\u001b[39msafe_reraise():\n\u001b[0;32m    617\u001b[0m         metadata\u001b[39m.\u001b[39m_remove_table(name, schema)\n",
      "File \u001b[1;32mc:\\Users\\filou\\anaconda3\\envs\\dashcanvas\\lib\\site-packages\\sqlalchemy\\util\\langhelpers.py:70\u001b[0m, in \u001b[0;36msafe_reraise.__exit__\u001b[1;34m(self, type_, value, traceback)\u001b[0m\n\u001b[0;32m     68\u001b[0m     \u001b[39mself\u001b[39m\u001b[39m.\u001b[39m_exc_info \u001b[39m=\u001b[39m \u001b[39mNone\u001b[39;00m  \u001b[39m# remove potential circular references\u001b[39;00m\n\u001b[0;32m     69\u001b[0m     \u001b[39mif\u001b[39;00m \u001b[39mnot\u001b[39;00m \u001b[39mself\u001b[39m\u001b[39m.\u001b[39mwarn_only:\n\u001b[1;32m---> 70\u001b[0m         compat\u001b[39m.\u001b[39;49mraise_(\n\u001b[0;32m     71\u001b[0m             exc_value,\n\u001b[0;32m     72\u001b[0m             with_traceback\u001b[39m=\u001b[39;49mexc_tb,\n\u001b[0;32m     73\u001b[0m         )\n\u001b[0;32m     74\u001b[0m \u001b[39melse\u001b[39;00m:\n\u001b[0;32m     75\u001b[0m     \u001b[39mif\u001b[39;00m \u001b[39mnot\u001b[39;00m compat\u001b[39m.\u001b[39mpy3k \u001b[39mand\u001b[39;00m \u001b[39mself\u001b[39m\u001b[39m.\u001b[39m_exc_info \u001b[39mand\u001b[39;00m \u001b[39mself\u001b[39m\u001b[39m.\u001b[39m_exc_info[\u001b[39m1\u001b[39m]:\n\u001b[0;32m     76\u001b[0m         \u001b[39m# emulate Py3K's behavior of telling us when an exception\u001b[39;00m\n\u001b[0;32m     77\u001b[0m         \u001b[39m# occurs in an exception handler.\u001b[39;00m\n",
      "File \u001b[1;32mc:\\Users\\filou\\anaconda3\\envs\\dashcanvas\\lib\\site-packages\\sqlalchemy\\util\\compat.py:208\u001b[0m, in \u001b[0;36mraise_\u001b[1;34m(***failed resolving arguments***)\u001b[0m\n\u001b[0;32m    205\u001b[0m     exception\u001b[39m.\u001b[39m__cause__ \u001b[39m=\u001b[39m replace_context\n\u001b[0;32m    207\u001b[0m \u001b[39mtry\u001b[39;00m:\n\u001b[1;32m--> 208\u001b[0m     \u001b[39mraise\u001b[39;00m exception\n\u001b[0;32m    209\u001b[0m \u001b[39mfinally\u001b[39;00m:\n\u001b[0;32m    210\u001b[0m     \u001b[39m# credit to\u001b[39;00m\n\u001b[0;32m    211\u001b[0m     \u001b[39m# https://cosmicpercolator.com/2016/01/13/exception-leaks-in-python-2-and-3/\u001b[39;00m\n\u001b[0;32m    212\u001b[0m     \u001b[39m# as the __traceback__ object creates a cycle\u001b[39;00m\n\u001b[0;32m    213\u001b[0m     \u001b[39mdel\u001b[39;00m exception, replace_context, from_, with_traceback\n",
      "File \u001b[1;32mc:\\Users\\filou\\anaconda3\\envs\\dashcanvas\\lib\\site-packages\\sqlalchemy\\sql\\schema.py:612\u001b[0m, in \u001b[0;36mTable.__new__\u001b[1;34m(cls, *args, **kw)\u001b[0m\n\u001b[0;32m    610\u001b[0m metadata\u001b[39m.\u001b[39m_add_table(name, schema, table)\n\u001b[0;32m    611\u001b[0m \u001b[39mtry\u001b[39;00m:\n\u001b[1;32m--> 612\u001b[0m     table\u001b[39m.\u001b[39m_init(name, metadata, \u001b[39m*\u001b[39margs, \u001b[39m*\u001b[39m\u001b[39m*\u001b[39mkw)\n\u001b[0;32m    613\u001b[0m     table\u001b[39m.\u001b[39mdispatch\u001b[39m.\u001b[39mafter_parent_attach(table, metadata)\n\u001b[0;32m    614\u001b[0m     \u001b[39mreturn\u001b[39;00m table\n",
      "File \u001b[1;32mc:\\Users\\filou\\anaconda3\\envs\\dashcanvas\\lib\\site-packages\\sqlalchemy\\sql\\schema.py:687\u001b[0m, in \u001b[0;36mTable._init\u001b[1;34m(self, name, metadata, *args, **kwargs)\u001b[0m\n\u001b[0;32m    683\u001b[0m \u001b[39m# load column definitions from the database if 'autoload' is defined\u001b[39;00m\n\u001b[0;32m    684\u001b[0m \u001b[39m# we do it after the table is in the singleton dictionary to support\u001b[39;00m\n\u001b[0;32m    685\u001b[0m \u001b[39m# circular foreign keys\u001b[39;00m\n\u001b[0;32m    686\u001b[0m \u001b[39mif\u001b[39;00m autoload:\n\u001b[1;32m--> 687\u001b[0m     \u001b[39mself\u001b[39;49m\u001b[39m.\u001b[39;49m_autoload(\n\u001b[0;32m    688\u001b[0m         metadata,\n\u001b[0;32m    689\u001b[0m         autoload_with,\n\u001b[0;32m    690\u001b[0m         include_columns,\n\u001b[0;32m    691\u001b[0m         _extend_on\u001b[39m=\u001b[39;49m_extend_on,\n\u001b[0;32m    692\u001b[0m         resolve_fks\u001b[39m=\u001b[39;49mresolve_fks,\n\u001b[0;32m    693\u001b[0m     )\n\u001b[0;32m    695\u001b[0m \u001b[39m# initialize all the column, etc. objects.  done after reflection to\u001b[39;00m\n\u001b[0;32m    696\u001b[0m \u001b[39m# allow user-overrides\u001b[39;00m\n\u001b[0;32m    698\u001b[0m \u001b[39mself\u001b[39m\u001b[39m.\u001b[39m_init_items(\n\u001b[0;32m    699\u001b[0m     \u001b[39m*\u001b[39margs,\n\u001b[0;32m    700\u001b[0m     allow_replacements\u001b[39m=\u001b[39mextend_existing \u001b[39mor\u001b[39;00m keep_existing \u001b[39mor\u001b[39;00m autoload\n\u001b[0;32m    701\u001b[0m )\n",
      "File \u001b[1;32mc:\\Users\\filou\\anaconda3\\envs\\dashcanvas\\lib\\site-packages\\sqlalchemy\\sql\\schema.py:720\u001b[0m, in \u001b[0;36mTable._autoload\u001b[1;34m(self, metadata, autoload_with, include_columns, exclude_columns, resolve_fks, _extend_on)\u001b[0m\n\u001b[0;32m    712\u001b[0m \u001b[39mif\u001b[39;00m autoload_with \u001b[39mis\u001b[39;00m \u001b[39mNone\u001b[39;00m:\n\u001b[0;32m    713\u001b[0m     autoload_with \u001b[39m=\u001b[39m _bind_or_error(\n\u001b[0;32m    714\u001b[0m         metadata,\n\u001b[0;32m    715\u001b[0m         msg\u001b[39m=\u001b[39m\u001b[39m\"\u001b[39m\u001b[39mNo engine is bound to this Table\u001b[39m\u001b[39m'\u001b[39m\u001b[39ms MetaData. \u001b[39m\u001b[39m\"\u001b[39m\n\u001b[0;32m    716\u001b[0m         \u001b[39m\"\u001b[39m\u001b[39mPass an engine to the Table via \u001b[39m\u001b[39m\"\u001b[39m\n\u001b[0;32m    717\u001b[0m         \u001b[39m\"\u001b[39m\u001b[39mautoload_with=<someengine_or_connection>\u001b[39m\u001b[39m\"\u001b[39m,\n\u001b[0;32m    718\u001b[0m     )\n\u001b[1;32m--> 720\u001b[0m insp \u001b[39m=\u001b[39m inspection\u001b[39m.\u001b[39;49minspect(autoload_with)\n\u001b[0;32m    721\u001b[0m \u001b[39mwith\u001b[39;00m insp\u001b[39m.\u001b[39m_inspection_context() \u001b[39mas\u001b[39;00m conn_insp:\n\u001b[0;32m    722\u001b[0m     conn_insp\u001b[39m.\u001b[39mreflect_table(\n\u001b[0;32m    723\u001b[0m         \u001b[39mself\u001b[39m,\n\u001b[0;32m    724\u001b[0m         include_columns,\n\u001b[1;32m   (...)\u001b[0m\n\u001b[0;32m    727\u001b[0m         _extend_on\u001b[39m=\u001b[39m_extend_on,\n\u001b[0;32m    728\u001b[0m     )\n",
      "File \u001b[1;32mc:\\Users\\filou\\anaconda3\\envs\\dashcanvas\\lib\\site-packages\\sqlalchemy\\inspection.py:64\u001b[0m, in \u001b[0;36minspect\u001b[1;34m(subject, raiseerr)\u001b[0m\n\u001b[0;32m     62\u001b[0m \u001b[39mif\u001b[39;00m reg \u001b[39mis\u001b[39;00m \u001b[39mTrue\u001b[39;00m:\n\u001b[0;32m     63\u001b[0m     \u001b[39mreturn\u001b[39;00m subject\n\u001b[1;32m---> 64\u001b[0m ret \u001b[39m=\u001b[39m reg(subject)\n\u001b[0;32m     65\u001b[0m \u001b[39mif\u001b[39;00m ret \u001b[39mis\u001b[39;00m \u001b[39mnot\u001b[39;00m \u001b[39mNone\u001b[39;00m:\n\u001b[0;32m     66\u001b[0m     \u001b[39mbreak\u001b[39;00m\n",
      "File \u001b[1;32mc:\\Users\\filou\\anaconda3\\envs\\dashcanvas\\lib\\site-packages\\sqlalchemy\\engine\\reflection.py:182\u001b[0m, in \u001b[0;36mInspector._engine_insp\u001b[1;34m(bind)\u001b[0m\n\u001b[0;32m    180\u001b[0m \u001b[39m@inspection\u001b[39m\u001b[39m.\u001b[39m_inspects(Engine)\n\u001b[0;32m    181\u001b[0m \u001b[39mdef\u001b[39;00m \u001b[39m_engine_insp\u001b[39m(bind):\n\u001b[1;32m--> 182\u001b[0m     \u001b[39mreturn\u001b[39;00m Inspector\u001b[39m.\u001b[39;49m_construct(Inspector\u001b[39m.\u001b[39;49m_init_engine, bind)\n",
      "File \u001b[1;32mc:\\Users\\filou\\anaconda3\\envs\\dashcanvas\\lib\\site-packages\\sqlalchemy\\engine\\reflection.py:117\u001b[0m, in \u001b[0;36mInspector._construct\u001b[1;34m(cls, init, bind)\u001b[0m\n\u001b[0;32m    114\u001b[0m     \u001b[39mcls\u001b[39m \u001b[39m=\u001b[39m bind\u001b[39m.\u001b[39mdialect\u001b[39m.\u001b[39minspector\n\u001b[0;32m    116\u001b[0m \u001b[39mself\u001b[39m \u001b[39m=\u001b[39m \u001b[39mcls\u001b[39m\u001b[39m.\u001b[39m\u001b[39m__new__\u001b[39m(\u001b[39mcls\u001b[39m)\n\u001b[1;32m--> 117\u001b[0m init(\u001b[39mself\u001b[39;49m, bind)\n\u001b[0;32m    118\u001b[0m \u001b[39mreturn\u001b[39;00m \u001b[39mself\u001b[39m\n",
      "File \u001b[1;32mc:\\Users\\filou\\anaconda3\\envs\\dashcanvas\\lib\\site-packages\\sqlalchemy\\engine\\reflection.py:128\u001b[0m, in \u001b[0;36mInspector._init_engine\u001b[1;34m(self, engine)\u001b[0m\n\u001b[0;32m    126\u001b[0m \u001b[39mdef\u001b[39;00m \u001b[39m_init_engine\u001b[39m(\u001b[39mself\u001b[39m, engine):\n\u001b[0;32m    127\u001b[0m     \u001b[39mself\u001b[39m\u001b[39m.\u001b[39mbind \u001b[39m=\u001b[39m \u001b[39mself\u001b[39m\u001b[39m.\u001b[39mengine \u001b[39m=\u001b[39m engine\n\u001b[1;32m--> 128\u001b[0m     engine\u001b[39m.\u001b[39;49mconnect()\u001b[39m.\u001b[39mclose()\n\u001b[0;32m    129\u001b[0m     \u001b[39mself\u001b[39m\u001b[39m.\u001b[39m_op_context_requires_connect \u001b[39m=\u001b[39m \u001b[39mTrue\u001b[39;00m\n\u001b[0;32m    130\u001b[0m     \u001b[39mself\u001b[39m\u001b[39m.\u001b[39mdialect \u001b[39m=\u001b[39m \u001b[39mself\u001b[39m\u001b[39m.\u001b[39mengine\u001b[39m.\u001b[39mdialect\n",
      "File \u001b[1;32mc:\\Users\\filou\\anaconda3\\envs\\dashcanvas\\lib\\site-packages\\sqlalchemy\\engine\\base.py:3315\u001b[0m, in \u001b[0;36mEngine.connect\u001b[1;34m(self, close_with_result)\u001b[0m\n\u001b[0;32m   3300\u001b[0m \u001b[39mdef\u001b[39;00m \u001b[39mconnect\u001b[39m(\u001b[39mself\u001b[39m, close_with_result\u001b[39m=\u001b[39m\u001b[39mFalse\u001b[39;00m):\n\u001b[0;32m   3301\u001b[0m     \u001b[39m\"\"\"Return a new :class:`_engine.Connection` object.\u001b[39;00m\n\u001b[0;32m   3302\u001b[0m \n\u001b[0;32m   3303\u001b[0m \u001b[39m    The :class:`_engine.Connection` object is a facade that uses a DBAPI\u001b[39;00m\n\u001b[1;32m   (...)\u001b[0m\n\u001b[0;32m   3312\u001b[0m \n\u001b[0;32m   3313\u001b[0m \u001b[39m    \"\"\"\u001b[39;00m\n\u001b[1;32m-> 3315\u001b[0m     \u001b[39mreturn\u001b[39;00m \u001b[39mself\u001b[39;49m\u001b[39m.\u001b[39;49m_connection_cls(\u001b[39mself\u001b[39;49m, close_with_result\u001b[39m=\u001b[39;49mclose_with_result)\n",
      "File \u001b[1;32mc:\\Users\\filou\\anaconda3\\envs\\dashcanvas\\lib\\site-packages\\sqlalchemy\\engine\\base.py:96\u001b[0m, in \u001b[0;36mConnection.__init__\u001b[1;34m(self, engine, connection, close_with_result, _branch_from, _execution_options, _dispatch, _has_events, _allow_revalidate)\u001b[0m\n\u001b[0;32m     91\u001b[0m     \u001b[39mself\u001b[39m\u001b[39m.\u001b[39m_has_events \u001b[39m=\u001b[39m _branch_from\u001b[39m.\u001b[39m_has_events\n\u001b[0;32m     92\u001b[0m \u001b[39melse\u001b[39;00m:\n\u001b[0;32m     93\u001b[0m     \u001b[39mself\u001b[39m\u001b[39m.\u001b[39m_dbapi_connection \u001b[39m=\u001b[39m (\n\u001b[0;32m     94\u001b[0m         connection\n\u001b[0;32m     95\u001b[0m         \u001b[39mif\u001b[39;00m connection \u001b[39mis\u001b[39;00m \u001b[39mnot\u001b[39;00m \u001b[39mNone\u001b[39;00m\n\u001b[1;32m---> 96\u001b[0m         \u001b[39melse\u001b[39;00m engine\u001b[39m.\u001b[39;49mraw_connection()\n\u001b[0;32m     97\u001b[0m     )\n\u001b[0;32m     99\u001b[0m     \u001b[39mself\u001b[39m\u001b[39m.\u001b[39m_transaction \u001b[39m=\u001b[39m \u001b[39mself\u001b[39m\u001b[39m.\u001b[39m_nested_transaction \u001b[39m=\u001b[39m \u001b[39mNone\u001b[39;00m\n\u001b[0;32m    100\u001b[0m     \u001b[39mself\u001b[39m\u001b[39m.\u001b[39m__savepoint_seq \u001b[39m=\u001b[39m \u001b[39m0\u001b[39m\n",
      "File \u001b[1;32mc:\\Users\\filou\\anaconda3\\envs\\dashcanvas\\lib\\site-packages\\sqlalchemy\\engine\\base.py:3394\u001b[0m, in \u001b[0;36mEngine.raw_connection\u001b[1;34m(self, _connection)\u001b[0m\n\u001b[0;32m   3372\u001b[0m \u001b[39mdef\u001b[39;00m \u001b[39mraw_connection\u001b[39m(\u001b[39mself\u001b[39m, _connection\u001b[39m=\u001b[39m\u001b[39mNone\u001b[39;00m):\n\u001b[0;32m   3373\u001b[0m     \u001b[39m\"\"\"Return a \"raw\" DBAPI connection from the connection pool.\u001b[39;00m\n\u001b[0;32m   3374\u001b[0m \n\u001b[0;32m   3375\u001b[0m \u001b[39m    The returned object is a proxied version of the DBAPI\u001b[39;00m\n\u001b[1;32m   (...)\u001b[0m\n\u001b[0;32m   3392\u001b[0m \n\u001b[0;32m   3393\u001b[0m \u001b[39m    \"\"\"\u001b[39;00m\n\u001b[1;32m-> 3394\u001b[0m     \u001b[39mreturn\u001b[39;00m \u001b[39mself\u001b[39;49m\u001b[39m.\u001b[39;49m_wrap_pool_connect(\u001b[39mself\u001b[39;49m\u001b[39m.\u001b[39;49mpool\u001b[39m.\u001b[39;49mconnect, _connection)\n",
      "File \u001b[1;32mc:\\Users\\filou\\anaconda3\\envs\\dashcanvas\\lib\\site-packages\\sqlalchemy\\engine\\base.py:3364\u001b[0m, in \u001b[0;36mEngine._wrap_pool_connect\u001b[1;34m(self, fn, connection)\u001b[0m\n\u001b[0;32m   3362\u001b[0m \u001b[39mexcept\u001b[39;00m dialect\u001b[39m.\u001b[39mdbapi\u001b[39m.\u001b[39mError \u001b[39mas\u001b[39;00m e:\n\u001b[0;32m   3363\u001b[0m     \u001b[39mif\u001b[39;00m connection \u001b[39mis\u001b[39;00m \u001b[39mNone\u001b[39;00m:\n\u001b[1;32m-> 3364\u001b[0m         Connection\u001b[39m.\u001b[39;49m_handle_dbapi_exception_noconnection(\n\u001b[0;32m   3365\u001b[0m             e, dialect, \u001b[39mself\u001b[39;49m\n\u001b[0;32m   3366\u001b[0m         )\n\u001b[0;32m   3367\u001b[0m     \u001b[39melse\u001b[39;00m:\n\u001b[0;32m   3368\u001b[0m         util\u001b[39m.\u001b[39mraise_(\n\u001b[0;32m   3369\u001b[0m             sys\u001b[39m.\u001b[39mexc_info()[\u001b[39m1\u001b[39m], with_traceback\u001b[39m=\u001b[39msys\u001b[39m.\u001b[39mexc_info()[\u001b[39m2\u001b[39m]\n\u001b[0;32m   3370\u001b[0m         )\n",
      "File \u001b[1;32mc:\\Users\\filou\\anaconda3\\envs\\dashcanvas\\lib\\site-packages\\sqlalchemy\\engine\\base.py:2198\u001b[0m, in \u001b[0;36mConnection._handle_dbapi_exception_noconnection\u001b[1;34m(cls, e, dialect, engine)\u001b[0m\n\u001b[0;32m   2196\u001b[0m     util\u001b[39m.\u001b[39mraise_(newraise, with_traceback\u001b[39m=\u001b[39mexc_info[\u001b[39m2\u001b[39m], from_\u001b[39m=\u001b[39me)\n\u001b[0;32m   2197\u001b[0m \u001b[39melif\u001b[39;00m should_wrap:\n\u001b[1;32m-> 2198\u001b[0m     util\u001b[39m.\u001b[39;49mraise_(\n\u001b[0;32m   2199\u001b[0m         sqlalchemy_exception, with_traceback\u001b[39m=\u001b[39;49mexc_info[\u001b[39m2\u001b[39;49m], from_\u001b[39m=\u001b[39;49me\n\u001b[0;32m   2200\u001b[0m     )\n\u001b[0;32m   2201\u001b[0m \u001b[39melse\u001b[39;00m:\n\u001b[0;32m   2202\u001b[0m     util\u001b[39m.\u001b[39mraise_(exc_info[\u001b[39m1\u001b[39m], with_traceback\u001b[39m=\u001b[39mexc_info[\u001b[39m2\u001b[39m])\n",
      "File \u001b[1;32mc:\\Users\\filou\\anaconda3\\envs\\dashcanvas\\lib\\site-packages\\sqlalchemy\\util\\compat.py:208\u001b[0m, in \u001b[0;36mraise_\u001b[1;34m(***failed resolving arguments***)\u001b[0m\n\u001b[0;32m    205\u001b[0m     exception\u001b[39m.\u001b[39m__cause__ \u001b[39m=\u001b[39m replace_context\n\u001b[0;32m    207\u001b[0m \u001b[39mtry\u001b[39;00m:\n\u001b[1;32m--> 208\u001b[0m     \u001b[39mraise\u001b[39;00m exception\n\u001b[0;32m    209\u001b[0m \u001b[39mfinally\u001b[39;00m:\n\u001b[0;32m    210\u001b[0m     \u001b[39m# credit to\u001b[39;00m\n\u001b[0;32m    211\u001b[0m     \u001b[39m# https://cosmicpercolator.com/2016/01/13/exception-leaks-in-python-2-and-3/\u001b[39;00m\n\u001b[0;32m    212\u001b[0m     \u001b[39m# as the __traceback__ object creates a cycle\u001b[39;00m\n\u001b[0;32m    213\u001b[0m     \u001b[39mdel\u001b[39;00m exception, replace_context, from_, with_traceback\n",
      "File \u001b[1;32mc:\\Users\\filou\\anaconda3\\envs\\dashcanvas\\lib\\site-packages\\sqlalchemy\\engine\\base.py:3361\u001b[0m, in \u001b[0;36mEngine._wrap_pool_connect\u001b[1;34m(self, fn, connection)\u001b[0m\n\u001b[0;32m   3359\u001b[0m dialect \u001b[39m=\u001b[39m \u001b[39mself\u001b[39m\u001b[39m.\u001b[39mdialect\n\u001b[0;32m   3360\u001b[0m \u001b[39mtry\u001b[39;00m:\n\u001b[1;32m-> 3361\u001b[0m     \u001b[39mreturn\u001b[39;00m fn()\n\u001b[0;32m   3362\u001b[0m \u001b[39mexcept\u001b[39;00m dialect\u001b[39m.\u001b[39mdbapi\u001b[39m.\u001b[39mError \u001b[39mas\u001b[39;00m e:\n\u001b[0;32m   3363\u001b[0m     \u001b[39mif\u001b[39;00m connection \u001b[39mis\u001b[39;00m \u001b[39mNone\u001b[39;00m:\n",
      "File \u001b[1;32mc:\\Users\\filou\\anaconda3\\envs\\dashcanvas\\lib\\site-packages\\sqlalchemy\\pool\\base.py:320\u001b[0m, in \u001b[0;36mPool.connect\u001b[1;34m(self)\u001b[0m\n\u001b[0;32m    312\u001b[0m \u001b[39mdef\u001b[39;00m \u001b[39mconnect\u001b[39m(\u001b[39mself\u001b[39m):\n\u001b[0;32m    313\u001b[0m     \u001b[39m\"\"\"Return a DBAPI connection from the pool.\u001b[39;00m\n\u001b[0;32m    314\u001b[0m \n\u001b[0;32m    315\u001b[0m \u001b[39m    The connection is instrumented such that when its\u001b[39;00m\n\u001b[1;32m   (...)\u001b[0m\n\u001b[0;32m    318\u001b[0m \n\u001b[0;32m    319\u001b[0m \u001b[39m    \"\"\"\u001b[39;00m\n\u001b[1;32m--> 320\u001b[0m     \u001b[39mreturn\u001b[39;00m _ConnectionFairy\u001b[39m.\u001b[39;49m_checkout(\u001b[39mself\u001b[39;49m)\n",
      "File \u001b[1;32mc:\\Users\\filou\\anaconda3\\envs\\dashcanvas\\lib\\site-packages\\sqlalchemy\\pool\\base.py:884\u001b[0m, in \u001b[0;36m_ConnectionFairy._checkout\u001b[1;34m(cls, pool, threadconns, fairy)\u001b[0m\n\u001b[0;32m    881\u001b[0m \u001b[39m@classmethod\u001b[39m\n\u001b[0;32m    882\u001b[0m \u001b[39mdef\u001b[39;00m \u001b[39m_checkout\u001b[39m(\u001b[39mcls\u001b[39m, pool, threadconns\u001b[39m=\u001b[39m\u001b[39mNone\u001b[39;00m, fairy\u001b[39m=\u001b[39m\u001b[39mNone\u001b[39;00m):\n\u001b[0;32m    883\u001b[0m     \u001b[39mif\u001b[39;00m \u001b[39mnot\u001b[39;00m fairy:\n\u001b[1;32m--> 884\u001b[0m         fairy \u001b[39m=\u001b[39m _ConnectionRecord\u001b[39m.\u001b[39;49mcheckout(pool)\n\u001b[0;32m    886\u001b[0m         fairy\u001b[39m.\u001b[39m_pool \u001b[39m=\u001b[39m pool\n\u001b[0;32m    887\u001b[0m         fairy\u001b[39m.\u001b[39m_counter \u001b[39m=\u001b[39m \u001b[39m0\u001b[39m\n",
      "File \u001b[1;32mc:\\Users\\filou\\anaconda3\\envs\\dashcanvas\\lib\\site-packages\\sqlalchemy\\pool\\base.py:486\u001b[0m, in \u001b[0;36m_ConnectionRecord.checkout\u001b[1;34m(cls, pool)\u001b[0m\n\u001b[0;32m    484\u001b[0m \u001b[39m@classmethod\u001b[39m\n\u001b[0;32m    485\u001b[0m \u001b[39mdef\u001b[39;00m \u001b[39mcheckout\u001b[39m(\u001b[39mcls\u001b[39m, pool):\n\u001b[1;32m--> 486\u001b[0m     rec \u001b[39m=\u001b[39m pool\u001b[39m.\u001b[39;49m_do_get()\n\u001b[0;32m    487\u001b[0m     \u001b[39mtry\u001b[39;00m:\n\u001b[0;32m    488\u001b[0m         dbapi_connection \u001b[39m=\u001b[39m rec\u001b[39m.\u001b[39mget_connection()\n",
      "File \u001b[1;32mc:\\Users\\filou\\anaconda3\\envs\\dashcanvas\\lib\\site-packages\\sqlalchemy\\pool\\impl.py:145\u001b[0m, in \u001b[0;36mQueuePool._do_get\u001b[1;34m(self)\u001b[0m\n\u001b[0;32m    143\u001b[0m         \u001b[39mreturn\u001b[39;00m \u001b[39mself\u001b[39m\u001b[39m.\u001b[39m_create_connection()\n\u001b[0;32m    144\u001b[0m     \u001b[39mexcept\u001b[39;00m:\n\u001b[1;32m--> 145\u001b[0m         \u001b[39mwith\u001b[39;00m util\u001b[39m.\u001b[39msafe_reraise():\n\u001b[0;32m    146\u001b[0m             \u001b[39mself\u001b[39m\u001b[39m.\u001b[39m_dec_overflow()\n\u001b[0;32m    147\u001b[0m \u001b[39melse\u001b[39;00m:\n",
      "File \u001b[1;32mc:\\Users\\filou\\anaconda3\\envs\\dashcanvas\\lib\\site-packages\\sqlalchemy\\util\\langhelpers.py:70\u001b[0m, in \u001b[0;36msafe_reraise.__exit__\u001b[1;34m(self, type_, value, traceback)\u001b[0m\n\u001b[0;32m     68\u001b[0m     \u001b[39mself\u001b[39m\u001b[39m.\u001b[39m_exc_info \u001b[39m=\u001b[39m \u001b[39mNone\u001b[39;00m  \u001b[39m# remove potential circular references\u001b[39;00m\n\u001b[0;32m     69\u001b[0m     \u001b[39mif\u001b[39;00m \u001b[39mnot\u001b[39;00m \u001b[39mself\u001b[39m\u001b[39m.\u001b[39mwarn_only:\n\u001b[1;32m---> 70\u001b[0m         compat\u001b[39m.\u001b[39;49mraise_(\n\u001b[0;32m     71\u001b[0m             exc_value,\n\u001b[0;32m     72\u001b[0m             with_traceback\u001b[39m=\u001b[39;49mexc_tb,\n\u001b[0;32m     73\u001b[0m         )\n\u001b[0;32m     74\u001b[0m \u001b[39melse\u001b[39;00m:\n\u001b[0;32m     75\u001b[0m     \u001b[39mif\u001b[39;00m \u001b[39mnot\u001b[39;00m compat\u001b[39m.\u001b[39mpy3k \u001b[39mand\u001b[39;00m \u001b[39mself\u001b[39m\u001b[39m.\u001b[39m_exc_info \u001b[39mand\u001b[39;00m \u001b[39mself\u001b[39m\u001b[39m.\u001b[39m_exc_info[\u001b[39m1\u001b[39m]:\n\u001b[0;32m     76\u001b[0m         \u001b[39m# emulate Py3K's behavior of telling us when an exception\u001b[39;00m\n\u001b[0;32m     77\u001b[0m         \u001b[39m# occurs in an exception handler.\u001b[39;00m\n",
      "File \u001b[1;32mc:\\Users\\filou\\anaconda3\\envs\\dashcanvas\\lib\\site-packages\\sqlalchemy\\util\\compat.py:208\u001b[0m, in \u001b[0;36mraise_\u001b[1;34m(***failed resolving arguments***)\u001b[0m\n\u001b[0;32m    205\u001b[0m     exception\u001b[39m.\u001b[39m__cause__ \u001b[39m=\u001b[39m replace_context\n\u001b[0;32m    207\u001b[0m \u001b[39mtry\u001b[39;00m:\n\u001b[1;32m--> 208\u001b[0m     \u001b[39mraise\u001b[39;00m exception\n\u001b[0;32m    209\u001b[0m \u001b[39mfinally\u001b[39;00m:\n\u001b[0;32m    210\u001b[0m     \u001b[39m# credit to\u001b[39;00m\n\u001b[0;32m    211\u001b[0m     \u001b[39m# https://cosmicpercolator.com/2016/01/13/exception-leaks-in-python-2-and-3/\u001b[39;00m\n\u001b[0;32m    212\u001b[0m     \u001b[39m# as the __traceback__ object creates a cycle\u001b[39;00m\n\u001b[0;32m    213\u001b[0m     \u001b[39mdel\u001b[39;00m exception, replace_context, from_, with_traceback\n",
      "File \u001b[1;32mc:\\Users\\filou\\anaconda3\\envs\\dashcanvas\\lib\\site-packages\\sqlalchemy\\pool\\impl.py:143\u001b[0m, in \u001b[0;36mQueuePool._do_get\u001b[1;34m(self)\u001b[0m\n\u001b[0;32m    141\u001b[0m \u001b[39mif\u001b[39;00m \u001b[39mself\u001b[39m\u001b[39m.\u001b[39m_inc_overflow():\n\u001b[0;32m    142\u001b[0m     \u001b[39mtry\u001b[39;00m:\n\u001b[1;32m--> 143\u001b[0m         \u001b[39mreturn\u001b[39;00m \u001b[39mself\u001b[39;49m\u001b[39m.\u001b[39;49m_create_connection()\n\u001b[0;32m    144\u001b[0m     \u001b[39mexcept\u001b[39;00m:\n\u001b[0;32m    145\u001b[0m         \u001b[39mwith\u001b[39;00m util\u001b[39m.\u001b[39msafe_reraise():\n",
      "File \u001b[1;32mc:\\Users\\filou\\anaconda3\\envs\\dashcanvas\\lib\\site-packages\\sqlalchemy\\pool\\base.py:266\u001b[0m, in \u001b[0;36mPool._create_connection\u001b[1;34m(self)\u001b[0m\n\u001b[0;32m    263\u001b[0m \u001b[39mdef\u001b[39;00m \u001b[39m_create_connection\u001b[39m(\u001b[39mself\u001b[39m):\n\u001b[0;32m    264\u001b[0m     \u001b[39m\"\"\"Called by subclasses to create a new ConnectionRecord.\"\"\"\u001b[39;00m\n\u001b[1;32m--> 266\u001b[0m     \u001b[39mreturn\u001b[39;00m _ConnectionRecord(\u001b[39mself\u001b[39;49m)\n",
      "File \u001b[1;32mc:\\Users\\filou\\anaconda3\\envs\\dashcanvas\\lib\\site-packages\\sqlalchemy\\pool\\base.py:381\u001b[0m, in \u001b[0;36m_ConnectionRecord.__init__\u001b[1;34m(self, pool, connect)\u001b[0m\n\u001b[0;32m    379\u001b[0m \u001b[39mself\u001b[39m\u001b[39m.\u001b[39m__pool \u001b[39m=\u001b[39m pool\n\u001b[0;32m    380\u001b[0m \u001b[39mif\u001b[39;00m connect:\n\u001b[1;32m--> 381\u001b[0m     \u001b[39mself\u001b[39;49m\u001b[39m.\u001b[39;49m__connect()\n\u001b[0;32m    382\u001b[0m \u001b[39mself\u001b[39m\u001b[39m.\u001b[39mfinalize_callback \u001b[39m=\u001b[39m deque()\n",
      "File \u001b[1;32mc:\\Users\\filou\\anaconda3\\envs\\dashcanvas\\lib\\site-packages\\sqlalchemy\\pool\\base.py:677\u001b[0m, in \u001b[0;36m_ConnectionRecord.__connect\u001b[1;34m(self)\u001b[0m\n\u001b[0;32m    675\u001b[0m     \u001b[39mself\u001b[39m\u001b[39m.\u001b[39mfresh \u001b[39m=\u001b[39m \u001b[39mTrue\u001b[39;00m\n\u001b[0;32m    676\u001b[0m \u001b[39mexcept\u001b[39;00m \u001b[39mException\u001b[39;00m \u001b[39mas\u001b[39;00m e:\n\u001b[1;32m--> 677\u001b[0m     \u001b[39mwith\u001b[39;00m util\u001b[39m.\u001b[39msafe_reraise():\n\u001b[0;32m    678\u001b[0m         pool\u001b[39m.\u001b[39mlogger\u001b[39m.\u001b[39mdebug(\u001b[39m\"\u001b[39m\u001b[39mError on connect(): \u001b[39m\u001b[39m%s\u001b[39;00m\u001b[39m\"\u001b[39m, e)\n\u001b[0;32m    679\u001b[0m \u001b[39melse\u001b[39;00m:\n\u001b[0;32m    680\u001b[0m     \u001b[39m# in SQLAlchemy 1.4 the first_connect event is not used by\u001b[39;00m\n\u001b[0;32m    681\u001b[0m     \u001b[39m# the engine, so this will usually not be set\u001b[39;00m\n",
      "File \u001b[1;32mc:\\Users\\filou\\anaconda3\\envs\\dashcanvas\\lib\\site-packages\\sqlalchemy\\util\\langhelpers.py:70\u001b[0m, in \u001b[0;36msafe_reraise.__exit__\u001b[1;34m(self, type_, value, traceback)\u001b[0m\n\u001b[0;32m     68\u001b[0m     \u001b[39mself\u001b[39m\u001b[39m.\u001b[39m_exc_info \u001b[39m=\u001b[39m \u001b[39mNone\u001b[39;00m  \u001b[39m# remove potential circular references\u001b[39;00m\n\u001b[0;32m     69\u001b[0m     \u001b[39mif\u001b[39;00m \u001b[39mnot\u001b[39;00m \u001b[39mself\u001b[39m\u001b[39m.\u001b[39mwarn_only:\n\u001b[1;32m---> 70\u001b[0m         compat\u001b[39m.\u001b[39;49mraise_(\n\u001b[0;32m     71\u001b[0m             exc_value,\n\u001b[0;32m     72\u001b[0m             with_traceback\u001b[39m=\u001b[39;49mexc_tb,\n\u001b[0;32m     73\u001b[0m         )\n\u001b[0;32m     74\u001b[0m \u001b[39melse\u001b[39;00m:\n\u001b[0;32m     75\u001b[0m     \u001b[39mif\u001b[39;00m \u001b[39mnot\u001b[39;00m compat\u001b[39m.\u001b[39mpy3k \u001b[39mand\u001b[39;00m \u001b[39mself\u001b[39m\u001b[39m.\u001b[39m_exc_info \u001b[39mand\u001b[39;00m \u001b[39mself\u001b[39m\u001b[39m.\u001b[39m_exc_info[\u001b[39m1\u001b[39m]:\n\u001b[0;32m     76\u001b[0m         \u001b[39m# emulate Py3K's behavior of telling us when an exception\u001b[39;00m\n\u001b[0;32m     77\u001b[0m         \u001b[39m# occurs in an exception handler.\u001b[39;00m\n",
      "File \u001b[1;32mc:\\Users\\filou\\anaconda3\\envs\\dashcanvas\\lib\\site-packages\\sqlalchemy\\util\\compat.py:208\u001b[0m, in \u001b[0;36mraise_\u001b[1;34m(***failed resolving arguments***)\u001b[0m\n\u001b[0;32m    205\u001b[0m     exception\u001b[39m.\u001b[39m__cause__ \u001b[39m=\u001b[39m replace_context\n\u001b[0;32m    207\u001b[0m \u001b[39mtry\u001b[39;00m:\n\u001b[1;32m--> 208\u001b[0m     \u001b[39mraise\u001b[39;00m exception\n\u001b[0;32m    209\u001b[0m \u001b[39mfinally\u001b[39;00m:\n\u001b[0;32m    210\u001b[0m     \u001b[39m# credit to\u001b[39;00m\n\u001b[0;32m    211\u001b[0m     \u001b[39m# https://cosmicpercolator.com/2016/01/13/exception-leaks-in-python-2-and-3/\u001b[39;00m\n\u001b[0;32m    212\u001b[0m     \u001b[39m# as the __traceback__ object creates a cycle\u001b[39;00m\n\u001b[0;32m    213\u001b[0m     \u001b[39mdel\u001b[39;00m exception, replace_context, from_, with_traceback\n",
      "File \u001b[1;32mc:\\Users\\filou\\anaconda3\\envs\\dashcanvas\\lib\\site-packages\\sqlalchemy\\pool\\base.py:673\u001b[0m, in \u001b[0;36m_ConnectionRecord.__connect\u001b[1;34m(self)\u001b[0m\n\u001b[0;32m    671\u001b[0m \u001b[39mtry\u001b[39;00m:\n\u001b[0;32m    672\u001b[0m     \u001b[39mself\u001b[39m\u001b[39m.\u001b[39mstarttime \u001b[39m=\u001b[39m time\u001b[39m.\u001b[39mtime()\n\u001b[1;32m--> 673\u001b[0m     \u001b[39mself\u001b[39m\u001b[39m.\u001b[39mdbapi_connection \u001b[39m=\u001b[39m connection \u001b[39m=\u001b[39m pool\u001b[39m.\u001b[39;49m_invoke_creator(\u001b[39mself\u001b[39;49m)\n\u001b[0;32m    674\u001b[0m     pool\u001b[39m.\u001b[39mlogger\u001b[39m.\u001b[39mdebug(\u001b[39m\"\u001b[39m\u001b[39mCreated new connection \u001b[39m\u001b[39m%r\u001b[39;00m\u001b[39m\"\u001b[39m, connection)\n\u001b[0;32m    675\u001b[0m     \u001b[39mself\u001b[39m\u001b[39m.\u001b[39mfresh \u001b[39m=\u001b[39m \u001b[39mTrue\u001b[39;00m\n",
      "File \u001b[1;32mc:\\Users\\filou\\anaconda3\\envs\\dashcanvas\\lib\\site-packages\\sqlalchemy\\engine\\create.py:578\u001b[0m, in \u001b[0;36mcreate_engine.<locals>.connect\u001b[1;34m(connection_record)\u001b[0m\n\u001b[0;32m    576\u001b[0m         \u001b[39mif\u001b[39;00m connection \u001b[39mis\u001b[39;00m \u001b[39mnot\u001b[39;00m \u001b[39mNone\u001b[39;00m:\n\u001b[0;32m    577\u001b[0m             \u001b[39mreturn\u001b[39;00m connection\n\u001b[1;32m--> 578\u001b[0m \u001b[39mreturn\u001b[39;00m dialect\u001b[39m.\u001b[39mconnect(\u001b[39m*\u001b[39mcargs, \u001b[39m*\u001b[39m\u001b[39m*\u001b[39mcparams)\n",
      "File \u001b[1;32mc:\\Users\\filou\\anaconda3\\envs\\dashcanvas\\lib\\site-packages\\sqlalchemy\\engine\\default.py:598\u001b[0m, in \u001b[0;36mDefaultDialect.connect\u001b[1;34m(self, *cargs, **cparams)\u001b[0m\n\u001b[0;32m    596\u001b[0m \u001b[39mdef\u001b[39;00m \u001b[39mconnect\u001b[39m(\u001b[39mself\u001b[39m, \u001b[39m*\u001b[39mcargs, \u001b[39m*\u001b[39m\u001b[39m*\u001b[39mcparams):\n\u001b[0;32m    597\u001b[0m     \u001b[39m# inherits the docstring from interfaces.Dialect.connect\u001b[39;00m\n\u001b[1;32m--> 598\u001b[0m     \u001b[39mreturn\u001b[39;00m \u001b[39mself\u001b[39m\u001b[39m.\u001b[39mdbapi\u001b[39m.\u001b[39mconnect(\u001b[39m*\u001b[39mcargs, \u001b[39m*\u001b[39m\u001b[39m*\u001b[39mcparams)\n",
      "File \u001b[1;32mc:\\Users\\filou\\anaconda3\\envs\\dashcanvas\\lib\\site-packages\\pymysql\\connections.py:353\u001b[0m, in \u001b[0;36mConnection.__init__\u001b[1;34m(self, user, password, host, database, unix_socket, port, charset, sql_mode, read_default_file, conv, use_unicode, client_flag, cursorclass, init_command, connect_timeout, read_default_group, autocommit, local_infile, max_allowed_packet, defer_connect, auth_plugin_map, read_timeout, write_timeout, bind_address, binary_prefix, program_name, server_public_key, ssl, ssl_ca, ssl_cert, ssl_disabled, ssl_key, ssl_verify_cert, ssl_verify_identity, compress, named_pipe, passwd, db)\u001b[0m\n\u001b[0;32m    351\u001b[0m     \u001b[39mself\u001b[39m\u001b[39m.\u001b[39m_sock \u001b[39m=\u001b[39m \u001b[39mNone\u001b[39;00m\n\u001b[0;32m    352\u001b[0m \u001b[39melse\u001b[39;00m:\n\u001b[1;32m--> 353\u001b[0m     \u001b[39mself\u001b[39;49m\u001b[39m.\u001b[39;49mconnect()\n",
      "File \u001b[1;32mc:\\Users\\filou\\anaconda3\\envs\\dashcanvas\\lib\\site-packages\\pymysql\\connections.py:664\u001b[0m, in \u001b[0;36mConnection.connect\u001b[1;34m(self, sock)\u001b[0m\n\u001b[0;32m    662\u001b[0m     \u001b[39mif\u001b[39;00m DEBUG:\n\u001b[0;32m    663\u001b[0m         \u001b[39mprint\u001b[39m(exc\u001b[39m.\u001b[39mtraceback)\n\u001b[1;32m--> 664\u001b[0m     \u001b[39mraise\u001b[39;00m exc\n\u001b[0;32m    666\u001b[0m \u001b[39m# If e is neither DatabaseError or IOError, It's a bug.\u001b[39;00m\n\u001b[0;32m    667\u001b[0m \u001b[39m# But raising AssertionError hides original error.\u001b[39;00m\n\u001b[0;32m    668\u001b[0m \u001b[39m# So just reraise it.\u001b[39;00m\n\u001b[0;32m    669\u001b[0m \u001b[39mraise\u001b[39;00m\n",
      "\u001b[1;31mOperationalError\u001b[0m: (pymysql.err.OperationalError) (2003, \"Can't connect to MySQL server on 'localhost' ([WinError 10061] Aucune connexion n’a pu être établie car l’ordinateur cible l’a expressément refusée)\")\n(Background on this error at: https://sqlalche.me/e/14/e3q8)"
     ]
    }
   ],
   "source": [
    "engine = connect_unix_socket()\n",
    "metadata = db.MetaData()\n",
    "users = db.Table('users', metadata, autoload=True, autoload_with=engine)"
   ]
  },
  {
   "cell_type": "code",
   "execution_count": null,
   "metadata": {},
   "outputs": [],
   "source": [
    "get_or_create(engine, )"
   ]
  },
  {
   "cell_type": "code",
   "execution_count": 7,
   "metadata": {},
   "outputs": [
    {
     "data": {
      "text/plain": [
       "{'iss': 'https://accounts.google.com',\n",
       " 'nbf': 1663711099,\n",
       " 'aud': '732264051436-0jgjer21ntnoi5ovilmgtqpghaj286sv.apps.googleusercontent.com',\n",
       " 'sub': '101453466175389613106',\n",
       " 'email': 'philippe.henri.saade@gmail.com',\n",
       " 'email_verified': True,\n",
       " 'azp': '732264051436-0jgjer21ntnoi5ovilmgtqpghaj286sv.apps.googleusercontent.com',\n",
       " 'name': 'Philippe Saade',\n",
       " 'picture': 'https://lh3.googleusercontent.com/a/ALm5wu2X09kT1I8_wy9bucsCyXwqPc69RV-9LSdYmnGQ=s96-c',\n",
       " 'given_name': 'Philippe',\n",
       " 'family_name': 'Saade',\n",
       " 'iat': 1663711399,\n",
       " 'exp': 1663714999,\n",
       " 'jti': 'a7320715a54262f564be795a65e53727673d9a82'}"
      ]
     },
     "execution_count": 7,
     "metadata": {},
     "output_type": "execute_result"
    }
   ],
   "source": [
    "idinfo"
   ]
  }
 ],
 "metadata": {
  "kernelspec": {
   "display_name": "Python 3.10.4 ('dashcanvas')",
   "language": "python",
   "name": "python3"
  },
  "language_info": {
   "codemirror_mode": {
    "name": "ipython",
    "version": 3
   },
   "file_extension": ".py",
   "mimetype": "text/x-python",
   "name": "python",
   "nbconvert_exporter": "python",
   "pygments_lexer": "ipython3",
   "version": "3.10.4"
  },
  "orig_nbformat": 4,
  "vscode": {
   "interpreter": {
    "hash": "df40e483d86b4f1080bf2c4e480fecb7bceb455f92b6f9ab31351dd115d305d9"
   }
  }
 },
 "nbformat": 4,
 "nbformat_minor": 2
}
